{
  "assetId": "head_1",
  "attachments": [],
  "displayName": "head_1",
  "pivot": {
    "x": 0.5,
    "y": 0.375,
    "z": 0.5625
  },
  "version": 2,
  "voxelSize": 0.0625,
  "voxels": [
    {
      "color": {
        "a": 255,
        "b": 201,
        "g": 201,
        "r": 201
      },
      "x": 5,
      "y": 8,
      "z": 7
    },
    {
      "color": {
        "a": 255,
        "b": 201,
        "g": 201,
        "r": 201
      },
      "x": 8,
      "y": 8,
      "z": 8
    },
    {
      "color": {
        "a": 255,
        "b": 193,
        "g": 193,
        "r": 193
      },
      "x": 4,
      "y": 7,
      "z": 10
    },
    {
      "color": {
        "a": 255,
        "b": 201,
        "g": 201,
        "r": 201
      },
      "x": 6,
      "y": 8,
      "z": 11
    },
    {
      "color": {
        "a": 255,
        "b": 201,
        "g": 201,
        "r": 201
      },
      "x": 7,
      "y": 8,
      "z": 8
    },
    {
      "color": {
        "a": 255,
        "b": 201,
        "g": 201,
        "r": 201
      },
      "x": 6,
      "y": 5,
      "z": 6
    },
    {
      "color": {
        "a": 255,
        "b": 201,
        "g": 201,
        "r": 201
      },
      "x": 8,
      "y": 3,
      "z": 6
    },
    {
      "color": {
        "a": 255,
        "b": 201,
        "g": 201,
        "r": 201
      },
      "x": 8,
      "y": 8,
      "z": 9
    },
    {
      "color": {
        "a": 255,
        "b": 201,
        "g": 201,
        "r": 201
      },
      "x": 7,
      "y": 8,
      "z": 9
    },
    {
      "color": {
        "a": 255,
        "b": 201,
        "g": 201,
        "r": 201
      },
      "x": 7,
      "y": 3,
      "z": 6
    },
    {
      "color": {
        "a": 255,
        "b": 201,
        "g": 201,
        "r": 201
      },
      "x": 6,
      "y": 8,
      "z": 8
    },
    {
      "color": {
        "a": 255,
        "b": 201,
        "g": 201,
        "r": 201
      },
      "x": 5,
      "y": 7,
      "z": 10
    },
    {
      "color": {
        "a": 255,
        "b": 201,
        "g": 201,
        "r": 201
      },
      "x": 7,
      "y": 8,
      "z": 11
    },
    {
      "color": {
        "a": 255,
        "b": 201,
        "g": 201,
        "r": 201
      },
      "x": 6,
      "y": 8,
      "z": 9
    },
    {
      "color": {
        "a": 255,
        "b": 201,
        "g": 201,
        "r": 201
      },
      "x": 6,
      "y": 3,
      "z": 6
    },
    {
      "color": {
        "a": 255,
        "b": 201,
        "g": 201,
        "r": 201
      },
      "x": 8,
      "y": 5,
      "z": 6
    },
    {
      "color": {
        "a": 255,
        "b": 201,
        "g": 201,
        "r": 201
      },
      "x": 5,
      "y": 8,
      "z": 8
    },
    {
      "color": {
        "a": 255,
        "b": 201,
        "g": 201,
        "r": 201
      },
      "x": 8,
      "y": 8,
      "z": 7
    },
    {
      "color": {
        "a": 255,
        "b": 201,
        "g": 201,
        "r": 201
      },
      "x": 6,
      "y": 7,
      "z": 10
    },
    {
      "color": {
        "a": 255,
        "b": 201,
        "g": 201,
        "r": 201
      },
      "x": 5,
      "y": 8,
      "z": 9
    },
    {
      "color": {
        "a": 255,
        "b": 201,
        "g": 201,
        "r": 201
      },
      "x": 5,
      "y": 3,
      "z": 6
    },
    {
      "color": {
        "a": 255,
        "b": 201,
        "g": 201,
        "r": 201
      },
      "x": 7,
      "y": 7,
      "z": 10
    },
    {
      "color": {
        "a": 255,
        "b": 201,
        "g": 201,
        "r": 201
      },
      "x": 5,
      "y": 8,
      "z": 11
    },
    {
      "color": {
        "a": 255,
        "b": 193,
        "g": 193,
        "r": 193
      },
      "x": 9,
      "y": 9,
      "z": 10
    },
    {
      "color": {
        "a": 255,
        "b": 201,
        "g": 201,
        "r": 201
      },
      "x": 6,
      "y": 8,
      "z": 7
    },
    {
      "color": {
        "a": 255,
        "b": 201,
        "g": 201,
        "r": 201
      },
      "x": 8,
      "y": 7,
      "z": 10
    },
    {
      "color": {
        "a": 255,
        "b": 201,
        "g": 201,
        "r": 201
      },
      "x": 9,
      "y": 8,
      "z": 9
    },
    {
      "color": {
        "a": 255,
        "b": 201,
        "g": 201,
        "r": 201
      },
      "x": 9,
      "y": 3,
      "z": 6
    },
    {
      "color": {
        "a": 255,
        "b": 201,
        "g": 201,
        "r": 201
      },
      "x": 9,
      "y": 8,
      "z": 8
    },
    {
      "color": {
        "a": 255,
        "b": 201,
        "g": 201,
        "r": 201
      },
      "x": 10,
      "y": 8,
      "z": 9
    },
    {
      "color": {
        "a": 255,
        "b": 201,
        "g": 201,
        "r": 201
      },
      "x": 10,
      "y": 3,
      "z": 6
    },
    {
      "color": {
        "a": 255,
        "b": 201,
        "g": 201,
        "r": 201
      },
      "x": 10,
      "y": 8,
      "z": 8
    },
    {
      "color": {
        "a": 255,
        "b": 201,
        "g": 201,
        "r": 201
      },
      "x": 5,
      "y": 7,
      "z": 8
    },
    {
      "color": {
        "a": 255,
        "b": 201,
        "g": 201,
        "r": 201
      },
      "x": 8,
      "y": 7,
      "z": 7
    },
    {
      "color": {
        "a": 255,
        "b": 201,
        "g": 201,
        "r": 201
      },
      "x": 7,
      "y": 8,
      "z": 10
    },
    {
      "color": {
        "a": 255,
        "b": 93,
        "g": 93,
        "r": 93
      },
      "x": 5,
      "y": 7,
      "z": 11
    },
    {
      "color": {
        "a": 255,
        "b": 201,
        "g": 201,
        "r": 201
      },
      "x": 7,
      "y": 7,
      "z": 11
    },
    {
      "color": {
        "a": 255,
        "b": 201,
        "g": 201,
        "r": 201
      },
      "x": 5,
      "y": 8,
      "z": 10
    },
    {
      "color": {
        "a": 255,
        "b": 201,
        "g": 201,
        "r": 201
      },
      "x": 6,
      "y": 7,
      "z": 8
    },
    {
      "color": {
        "a": 255,
        "b": 201,
        "g": 201,
        "r": 201
      },
      "x": 8,
      "y": 8,
      "z": 10
    },
    {
      "color": {
        "a": 255,
        "b": 201,
        "g": 201,
        "r": 201
      },
      "x": 6,
      "y": 7,
      "z": 7
    },
    {
      "color": {
        "a": 255,
        "b": 201,
        "g": 201,
        "r": 201
      },
      "x": 9,
      "y": 8,
      "z": 10
    },
    {
      "color": {
        "a": 255,
        "b": 201,
        "g": 201,
        "r": 201
      },
      "x": 10,
      "y": 8,
      "z": 7
    },
    {
      "color": {
        "a": 255,
        "b": 201,
        "g": 201,
        "r": 201
      },
      "x": 10,
      "y": 8,
      "z": 10
    },
    {
      "color": {
        "a": 255,
        "b": 201,
        "g": 201,
        "r": 201
      },
      "x": 9,
      "y": 8,
      "z": 7
    },
    {
      "color": {
        "a": 255,
        "b": 201,
        "g": 201,
        "r": 201
      },
      "x": 7,
      "y": 8,
      "z": 7
    },
    {
      "color": {
        "a": 255,
        "b": 201,
        "g": 201,
        "r": 201
      },
      "x": 8,
      "y": 8,
      "z": 11
    },
    {
      "color": {
        "a": 255,
        "b": 201,
        "g": 201,
        "r": 201
      },
      "x": 9,
      "y": 8,
      "z": 11
    },
    {
      "color": {
        "a": 255,
        "b": 193,
        "g": 193,
        "r": 193
      },
      "x": 5,
      "y": 9,
      "z": 10
    },
    {
      "color": {
        "a": 255,
        "b": 180,
        "g": 180,
        "r": 180
      },
      "x": 8,
      "y": 5,
      "z": 5
    },
    {
      "color": {
        "a": 255,
        "b": 201,
        "g": 201,
        "r": 201
      },
      "x": 10,
      "y": 8,
      "z": 11
    },
    {
      "color": {
        "a": 255,
        "b": 193,
        "g": 193,
        "r": 193
      },
      "x": 4,
      "y": 8,
      "z": 10
    },
    {
      "color": {
        "a": 255,
        "b": 93,
        "g": 93,
        "r": 93
      },
      "x": 6,
      "y": 7,
      "z": 11
    },
    {
      "color": {
        "a": 255,
        "b": 201,
        "g": 201,
        "r": 201
      },
      "x": 7,
      "y": 7,
      "z": 8
    },
    {
      "color": {
        "a": 255,
        "b": 193,
        "g": 193,
        "r": 193
      },
      "x": 9,
      "y": 9,
      "z": 8
    },
    {
      "color": {
        "a": 255,
        "b": 201,
        "g": 201,
        "r": 201
      },
      "x": 8,
      "y": 7,
      "z": 11
    },
    {
      "color": {
        "a": 255,
        "b": 201,
        "g": 201,
        "r": 201
      },
      "x": 8,
      "y": 7,
      "z": 8
    },
    {
      "color": {
        "a": 255,
        "b": 201,
        "g": 201,
        "r": 201
      },
      "x": 5,
      "y": 7,
      "z": 7
    },
    {
      "color": {
        "a": 255,
        "b": 201,
        "g": 201,
        "r": 201
      },
      "x": 10,
      "y": 7,
      "z": 9
    },
    {
      "color": {
        "a": 255,
        "b": 201,
        "g": 201,
        "r": 201
      },
      "x": 9,
      "y": 7,
      "z": 9
    },
    {
      "color": {
        "a": 255,
        "b": 193,
        "g": 193,
        "r": 193
      },
      "x": 7,
      "y": 9,
      "z": 9
    },
    {
      "color": {
        "a": 255,
        "b": 201,
        "g": 201,
        "r": 201
      },
      "x": 9,
      "y": 7,
      "z": 10
    },
    {
      "color": {
        "a": 255,
        "b": 193,
        "g": 193,
        "r": 193
      },
      "x": 7,
      "y": 9,
      "z": 10
    },
    {
      "color": {
        "a": 255,
        "b": 201,
        "g": 201,
        "r": 201
      },
      "x": 10,
      "y": 7,
      "z": 7
    },
    {
      "color": {
        "a": 255,
        "b": 201,
        "g": 201,
        "r": 201
      },
      "x": 6,
      "y": 7,
      "z": 9
    },
    {
      "color": {
        "a": 255,
        "b": 201,
        "g": 201,
        "r": 201
      },
      "x": 8,
      "y": 6,
      "z": 6
    },
    {
      "color": {
        "a": 255,
        "b": 201,
        "g": 201,
        "r": 201
      },
      "x": 5,
      "y": 7,
      "z": 9
    },
    {
      "color": {
        "a": 255,
        "b": 201,
        "g": 201,
        "r": 201
      },
      "x": 7,
      "y": 7,
      "z": 9
    },
    {
      "color": {
        "a": 255,
        "b": 193,
        "g": 193,
        "r": 193
      },
      "x": 9,
      "y": 9,
      "z": 9
    },
    {
      "color": {
        "a": 255,
        "b": 201,
        "g": 201,
        "r": 201
      },
      "x": 6,
      "y": 6,
      "z": 6
    },
    {
      "color": {
        "a": 255,
        "b": 201,
        "g": 201,
        "r": 201
      },
      "x": 8,
      "y": 7,
      "z": 9
    },
    {
      "color": {
        "a": 255,
        "b": 201,
        "g": 201,
        "r": 201
      },
      "x": 9,
      "y": 7,
      "z": 7
    },
    {
      "color": {
        "a": 255,
        "b": 193,
        "g": 193,
        "r": 193
      },
      "x": 7,
      "y": 9,
      "z": 7
    },
    {
      "color": {
        "a": 255,
        "b": 201,
        "g": 201,
        "r": 201
      },
      "x": 10,
      "y": 7,
      "z": 10
    },
    {
      "color": {
        "a": 255,
        "b": 201,
        "g": 201,
        "r": 201
      },
      "x": 7,
      "y": 7,
      "z": 7
    },
    {
      "color": {
        "a": 255,
        "b": 193,
        "g": 193,
        "r": 193
      },
      "x": 9,
      "y": 9,
      "z": 7
    },
    {
      "color": {
        "a": 255,
        "b": 201,
        "g": 201,
        "r": 201
      },
      "x": 9,
      "y": 7,
      "z": 8
    },
    {
      "color": {
        "a": 255,
        "b": 193,
        "g": 193,
        "r": 193
      },
      "x": 7,
      "y": 9,
      "z": 8
    },
    {
      "color": {
        "a": 255,
        "b": 201,
        "g": 201,
        "r": 201
      },
      "x": 7,
      "y": 5,
      "z": 10
    },
    {
      "color": {
        "a": 255,
        "b": 201,
        "g": 201,
        "r": 201
      },
      "x": 5,
      "y": 6,
      "z": 11
    },
    {
      "color": {
        "a": 255,
        "b": 201,
        "g": 201,
        "r": 201
      },
      "x": 7,
      "y": 5,
      "z": 11
    },
    {
      "color": {
        "a": 255,
        "b": 201,
        "g": 201,
        "r": 201
      },
      "x": 5,
      "y": 6,
      "z": 10
    },
    {
      "color": {
        "a": 255,
        "b": 193,
        "g": 193,
        "r": 193
      },
      "x": 11,
      "y": 8,
      "z": 6
    },
    {
      "color": {
        "a": 255,
        "b": 201,
        "g": 201,
        "r": 201
      },
      "x": 5,
      "y": 6,
      "z": 9
    },
    {
      "color": {
        "a": 255,
        "b": 201,
        "g": 201,
        "r": 201
      },
      "x": 5,
      "y": 6,
      "z": 8
    },
    {
      "color": {
        "a": 255,
        "b": 201,
        "g": 201,
        "r": 201
      },
      "x": 5,
      "y": 6,
      "z": 7
    },
    {
      "color": {
        "a": 255,
        "b": 201,
        "g": 201,
        "r": 201
      },
      "x": 6,
      "y": 6,
      "z": 7
    },
    {
      "color": {
        "a": 255,
        "b": 201,
        "g": 201,
        "r": 201
      },
      "x": 6,
      "y": 6,
      "z": 8
    },
    {
      "color": {
        "a": 255,
        "b": 201,
        "g": 201,
        "r": 201
      },
      "x": 8,
      "y": 7,
      "z": 6
    },
    {
      "color": {
        "a": 255,
        "b": 201,
        "g": 201,
        "r": 201
      },
      "x": 6,
      "y": 6,
      "z": 9
    },
    {
      "color": {
        "a": 255,
        "b": 201,
        "g": 201,
        "r": 201
      },
      "x": 5,
      "y": 5,
      "z": 10
    },
    {
      "color": {
        "a": 255,
        "b": 201,
        "g": 201,
        "r": 201
      },
      "x": 7,
      "y": 6,
      "z": 11
    },
    {
      "color": {
        "a": 255,
        "b": 193,
        "g": 193,
        "r": 193
      },
      "x": 8,
      "y": 9,
      "z": 5
    },
    {
      "color": {
        "a": 255,
        "b": 193,
        "g": 193,
        "r": 193
      },
      "x": 11,
      "y": 7,
      "z": 6
    },
    {
      "color": {
        "a": 255,
        "b": 201,
        "g": 201,
        "r": 201
      },
      "x": 7,
      "y": 6,
      "z": 10
    },
    {
      "color": {
        "a": 255,
        "b": 180,
        "g": 180,
        "r": 180
      },
      "x": 5,
      "y": 5,
      "z": 11
    },
    {
      "color": {
        "a": 255,
        "b": 201,
        "g": 201,
        "r": 201
      },
      "x": 7,
      "y": 6,
      "z": 9
    },
    {
      "color": {
        "a": 255,
        "b": 201,
        "g": 201,
        "r": 201
      },
      "x": 7,
      "y": 6,
      "z": 8
    },
    {
      "color": {
        "a": 255,
        "b": 201,
        "g": 201,
        "r": 201
      },
      "x": 8,
      "y": 6,
      "z": 8
    },
    {
      "color": {
        "a": 255,
        "b": 201,
        "g": 201,
        "r": 201
      },
      "x": 6,
      "y": 7,
      "z": 6
    },
    {
      "color": {
        "a": 255,
        "b": 201,
        "g": 201,
        "r": 201
      },
      "x": 8,
      "y": 6,
      "z": 9
    },
    {
      "color": {
        "a": 255,
        "b": 201,
        "g": 201,
        "r": 201
      },
      "x": 8,
      "y": 6,
      "z": 10
    },
    {
      "color": {
        "a": 255,
        "b": 201,
        "g": 201,
        "r": 201
      },
      "x": 8,
      "y": 6,
      "z": 11
    },
    {
      "color": {
        "a": 255,
        "b": 193,
        "g": 193,
        "r": 193
      },
      "x": 9,
      "y": 7,
      "z": 5
    },
    {
      "color": {
        "a": 255,
        "b": 193,
        "g": 193,
        "r": 193
      },
      "x": 7,
      "y": 9,
      "z": 5
    },
    {
      "color": {
        "a": 255,
        "b": 201,
        "g": 201,
        "r": 201
      },
      "x": 9,
      "y": 6,
      "z": 10
    },
    {
      "color": {
        "a": 255,
        "b": 201,
        "g": 201,
        "r": 201
      },
      "x": 9,
      "y": 6,
      "z": 9
    },
    {
      "color": {
        "a": 255,
        "b": 201,
        "g": 201,
        "r": 201
      },
      "x": 9,
      "y": 6,
      "z": 8
    },
    {
      "color": {
        "a": 255,
        "b": 201,
        "g": 201,
        "r": 201
      },
      "x": 10,
      "y": 6,
      "z": 9
    },
    {
      "color": {
        "a": 255,
        "b": 201,
        "g": 201,
        "r": 201
      },
      "x": 10,
      "y": 6,
      "z": 10
    },
    {
      "color": {
        "a": 255,
        "b": 201,
        "g": 201,
        "r": 201
      },
      "x": 10,
      "y": 6,
      "z": 11
    },
    {
      "color": {
        "a": 255,
        "b": 201,
        "g": 201,
        "r": 201
      },
      "x": 10,
      "y": 6,
      "z": 8
    },
    {
      "color": {
        "a": 255,
        "b": 201,
        "g": 201,
        "r": 201
      },
      "x": 10,
      "y": 6,
      "z": 7
    },
    {
      "color": {
        "a": 255,
        "b": 201,
        "g": 201,
        "r": 201
      },
      "x": 9,
      "y": 6,
      "z": 7
    },
    {
      "color": {
        "a": 255,
        "b": 201,
        "g": 201,
        "r": 201
      },
      "x": 8,
      "y": 6,
      "z": 7
    },
    {
      "color": {
        "a": 255,
        "b": 201,
        "g": 201,
        "r": 201
      },
      "x": 7,
      "y": 6,
      "z": 7
    },
    {
      "color": {
        "a": 255,
        "b": 201,
        "g": 201,
        "r": 201
      },
      "x": 5,
      "y": 5,
      "z": 9
    },
    {
      "color": {
        "a": 255,
        "b": 201,
        "g": 201,
        "r": 201
      },
      "x": 8,
      "y": 8,
      "z": 6
    },
    {
      "color": {
        "a": 255,
        "b": 201,
        "g": 201,
        "r": 201
      },
      "x": 8,
      "y": 3,
      "z": 9
    },
    {
      "color": {
        "a": 255,
        "b": 201,
        "g": 201,
        "r": 201
      },
      "x": 6,
      "y": 5,
      "z": 9
    },
    {
      "color": {
        "a": 255,
        "b": 201,
        "g": 201,
        "r": 201
      },
      "x": 8,
      "y": 3,
      "z": 10
    },
    {
      "color": {
        "a": 255,
        "b": 201,
        "g": 201,
        "r": 201
      },
      "x": 6,
      "y": 5,
      "z": 10
    },
    {
      "color": {
        "a": 255,
        "b": 201,
        "g": 201,
        "r": 201
      },
      "x": 8,
      "y": 3,
      "z": 11
    },
    {
      "color": {
        "a": 255,
        "b": 201,
        "g": 201,
        "r": 201
      },
      "x": 6,
      "y": 5,
      "z": 11
    },
    {
      "color": {
        "a": 255,
        "b": 193,
        "g": 193,
        "r": 193
      },
      "x": 4,
      "y": 6,
      "z": 10
    },
    {
      "color": {
        "a": 255,
        "b": 201,
        "g": 201,
        "r": 201
      },
      "x": 6,
      "y": 3,
      "z": 11
    },
    {
      "color": {
        "a": 255,
        "b": 201,
        "g": 201,
        "r": 201
      },
      "x": 8,
      "y": 5,
      "z": 11
    },
    {
      "color": {
        "a": 255,
        "b": 193,
        "g": 193,
        "r": 193
      },
      "x": 9,
      "y": 8,
      "z": 5
    },
    {
      "color": {
        "a": 255,
        "b": 201,
        "g": 201,
        "r": 201
      },
      "x": 6,
      "y": 3,
      "z": 10
    },
    {
      "color": {
        "a": 255,
        "b": 201,
        "g": 201,
        "r": 201
      },
      "x": 8,
      "y": 5,
      "z": 10
    },
    {
      "color": {
        "a": 255,
        "b": 193,
        "g": 193,
        "r": 193
      },
      "x": 5,
      "y": 9,
      "z": 5
    },
    {
      "color": {
        "a": 255,
        "b": 201,
        "g": 201,
        "r": 201
      },
      "x": 6,
      "y": 8,
      "z": 6
    },
    {
      "color": {
        "a": 255,
        "b": 201,
        "g": 201,
        "r": 201
      },
      "x": 6,
      "y": 3,
      "z": 9
    },
    {
      "color": {
        "a": 255,
        "b": 201,
        "g": 201,
        "r": 201
      },
      "x": 8,
      "y": 5,
      "z": 9
    },
    {
      "color": {
        "a": 255,
        "b": 201,
        "g": 201,
        "r": 201
      },
      "x": 7,
      "y": 5,
      "z": 9
    },
    {
      "color": {
        "a": 255,
        "b": 201,
        "g": 201,
        "r": 201
      },
      "x": 9,
      "y": 5,
      "z": 10
    },
    {
      "color": {
        "a": 255,
        "b": 201,
        "g": 201,
        "r": 201
      },
      "x": 9,
      "y": 5,
      "z": 11
    },
    {
      "color": {
        "a": 255,
        "b": 193,
        "g": 193,
        "r": 193
      },
      "x": 8,
      "y": 8,
      "z": 5
    },
    {
      "color": {
        "a": 255,
        "b": 180,
        "g": 180,
        "r": 180
      },
      "x": 7,
      "y": 4,
      "z": 5
    },
    {
      "color": {
        "a": 255,
        "b": 180,
        "g": 180,
        "r": 180
      },
      "x": 10,
      "y": 5,
      "z": 11
    },
    {
      "color": {
        "a": 255,
        "b": 201,
        "g": 201,
        "r": 201
      },
      "x": 10,
      "y": 5,
      "z": 10
    },
    {
      "color": {
        "a": 255,
        "b": 201,
        "g": 201,
        "r": 201
      },
      "x": 10,
      "y": 5,
      "z": 9
    },
    {
      "color": {
        "a": 255,
        "b": 201,
        "g": 201,
        "r": 201
      },
      "x": 10,
      "y": 5,
      "z": 8
    },
    {
      "color": {
        "a": 255,
        "b": 201,
        "g": 201,
        "r": 201
      },
      "x": 9,
      "y": 5,
      "z": 8
    },
    {
      "color": {
        "a": 255,
        "b": 201,
        "g": 201,
        "r": 201
      },
      "x": 6,
      "y": 3,
      "z": 8
    },
    {
      "color": {
        "a": 255,
        "b": 201,
        "g": 201,
        "r": 201
      },
      "x": 8,
      "y": 5,
      "z": 8
    },
    {
      "color": {
        "a": 255,
        "b": 201,
        "g": 201,
        "r": 201
      },
      "x": 7,
      "y": 5,
      "z": 8
    },
    {
      "color": {
        "a": 255,
        "b": 201,
        "g": 201,
        "r": 201
      },
      "x": 8,
      "y": 3,
      "z": 8
    },
    {
      "color": {
        "a": 255,
        "b": 201,
        "g": 201,
        "r": 201
      },
      "x": 6,
      "y": 5,
      "z": 8
    },
    {
      "color": {
        "a": 255,
        "b": 201,
        "g": 201,
        "r": 201
      },
      "x": 5,
      "y": 5,
      "z": 8
    },
    {
      "color": {
        "a": 255,
        "b": 201,
        "g": 201,
        "r": 201
      },
      "x": 9,
      "y": 5,
      "z": 9
    },
    {
      "color": {
        "a": 255,
        "b": 201,
        "g": 201,
        "r": 201
      },
      "x": 5,
      "y": 5,
      "z": 7
    },
    {
      "color": {
        "a": 255,
        "b": 201,
        "g": 201,
        "r": 201
      },
      "x": 8,
      "y": 3,
      "z": 7
    },
    {
      "color": {
        "a": 255,
        "b": 201,
        "g": 201,
        "r": 201
      },
      "x": 6,
      "y": 5,
      "z": 7
    },
    {
      "color": {
        "a": 255,
        "b": 201,
        "g": 201,
        "r": 201
      },
      "x": 7,
      "y": 5,
      "z": 7
    },
    {
      "color": {
        "a": 255,
        "b": 201,
        "g": 201,
        "r": 201
      },
      "x": 6,
      "y": 3,
      "z": 7
    },
    {
      "color": {
        "a": 255,
        "b": 201,
        "g": 201,
        "r": 201
      },
      "x": 8,
      "y": 5,
      "z": 7
    },
    {
      "color": {
        "a": 255,
        "b": 201,
        "g": 201,
        "r": 201
      },
      "x": 9,
      "y": 5,
      "z": 7
    },
    {
      "color": {
        "a": 255,
        "b": 201,
        "g": 201,
        "r": 201
      },
      "x": 10,
      "y": 5,
      "z": 7
    },
    {
      "color": {
        "a": 255,
        "b": 201,
        "g": 201,
        "r": 201
      },
      "x": 5,
      "y": 4,
      "z": 11
    },
    {
      "color": {
        "a": 255,
        "b": 201,
        "g": 201,
        "r": 201
      },
      "x": 5,
      "y": 4,
      "z": 9
    },
    {
      "color": {
        "a": 255,
        "b": 201,
        "g": 201,
        "r": 201
      },
      "x": 5,
      "y": 4,
      "z": 8
    },
    {
      "color": {
        "a": 255,
        "b": 201,
        "g": 201,
        "r": 201
      },
      "x": 5,
      "y": 4,
      "z": 7
    },
    {
      "color": {
        "a": 255,
        "b": 201,
        "g": 201,
        "r": 201
      },
      "x": 6,
      "y": 4,
      "z": 7
    },
    {
      "color": {
        "a": 255,
        "b": 201,
        "g": 201,
        "r": 201
      },
      "x": 6,
      "y": 4,
      "z": 8
    },
    {
      "color": {
        "a": 255,
        "b": 201,
        "g": 201,
        "r": 201
      },
      "x": 6,
      "y": 4,
      "z": 9
    },
    {
      "color": {
        "a": 255,
        "b": 201,
        "g": 201,
        "r": 201
      },
      "x": 9,
      "y": 4,
      "z": 10
    },
    {
      "color": {
        "a": 255,
        "b": 201,
        "g": 201,
        "r": 201
      },
      "x": 10,
      "y": 4,
      "z": 11
    },
    {
      "color": {
        "a": 255,
        "b": 180,
        "g": 180,
        "r": 180
      },
      "x": 7,
      "y": 5,
      "z": 5
    },
    {
      "color": {
        "a": 255,
        "b": 201,
        "g": 201,
        "r": 201
      },
      "x": 10,
      "y": 4,
      "z": 10
    },
    {
      "color": {
        "a": 255,
        "b": 201,
        "g": 201,
        "r": 201
      },
      "x": 8,
      "y": 4,
      "z": 9
    },
    {
      "color": {
        "a": 255,
        "b": 201,
        "g": 201,
        "r": 201
      },
      "x": 9,
      "y": 4,
      "z": 9
    },
    {
      "color": {
        "a": 255,
        "b": 201,
        "g": 201,
        "r": 201
      },
      "x": 7,
      "y": 4,
      "z": 9
    },
    {
      "color": {
        "a": 255,
        "b": 201,
        "g": 201,
        "r": 201
      },
      "x": 7,
      "y": 4,
      "z": 8
    },
    {
      "color": {
        "a": 255,
        "b": 201,
        "g": 201,
        "r": 201
      },
      "x": 8,
      "y": 4,
      "z": 8
    },
    {
      "color": {
        "a": 255,
        "b": 193,
        "g": 193,
        "r": 193
      },
      "x": 4,
      "y": 7,
      "z": 7
    },
    {
      "color": {
        "a": 255,
        "b": 201,
        "g": 201,
        "r": 201
      },
      "x": 7,
      "y": 4,
      "z": 7
    },
    {
      "color": {
        "a": 255,
        "b": 201,
        "g": 201,
        "r": 201
      },
      "x": 8,
      "y": 4,
      "z": 7
    },
    {
      "color": {
        "a": 255,
        "b": 193,
        "g": 193,
        "r": 193
      },
      "x": 4,
      "y": 7,
      "z": 8
    },
    {
      "color": {
        "a": 255,
        "b": 201,
        "g": 201,
        "r": 201
      },
      "x": 9,
      "y": 4,
      "z": 8
    },
    {
      "color": {
        "a": 255,
        "b": 201,
        "g": 201,
        "r": 201
      },
      "x": 10,
      "y": 4,
      "z": 9
    },
    {
      "color": {
        "a": 255,
        "b": 201,
        "g": 201,
        "r": 201
      },
      "x": 10,
      "y": 4,
      "z": 8
    },
    {
      "color": {
        "a": 255,
        "b": 201,
        "g": 201,
        "r": 201
      },
      "x": 10,
      "y": 4,
      "z": 7
    },
    {
      "color": {
        "a": 255,
        "b": 201,
        "g": 201,
        "r": 201
      },
      "x": 9,
      "y": 4,
      "z": 7
    },
    {
      "color": {
        "a": 255,
        "b": 201,
        "g": 201,
        "r": 201
      },
      "x": 7,
      "y": 3,
      "z": 11
    },
    {
      "color": {
        "a": 255,
        "b": 193,
        "g": 193,
        "r": 193
      },
      "x": 11,
      "y": 5,
      "z": 9
    },
    {
      "color": {
        "a": 255,
        "b": 201,
        "g": 201,
        "r": 201
      },
      "x": 9,
      "y": 3,
      "z": 11
    },
    {
      "color": {
        "a": 255,
        "b": 193,
        "g": 193,
        "r": 193
      },
      "x": 6,
      "y": 8,
      "z": 5
    },
    {
      "color": {
        "a": 255,
        "b": 201,
        "g": 201,
        "r": 201
      },
      "x": 10,
      "y": 8,
      "z": 6
    },
    {
      "color": {
        "a": 255,
        "b": 201,
        "g": 201,
        "r": 201
      },
      "x": 10,
      "y": 3,
      "z": 9
    },
    {
      "color": {
        "a": 255,
        "b": 201,
        "g": 201,
        "r": 201
      },
      "x": 9,
      "y": 8,
      "z": 6
    },
    {
      "color": {
        "a": 255,
        "b": 201,
        "g": 201,
        "r": 201
      },
      "x": 9,
      "y": 3,
      "z": 9
    },
    {
      "color": {
        "a": 255,
        "b": 201,
        "g": 201,
        "r": 201
      },
      "x": 9,
      "y": 3,
      "z": 10
    },
    {
      "color": {
        "a": 255,
        "b": 201,
        "g": 201,
        "r": 201
      },
      "x": 7,
      "y": 3,
      "z": 10
    },
    {
      "color": {
        "a": 255,
        "b": 201,
        "g": 201,
        "r": 201
      },
      "x": 7,
      "y": 8,
      "z": 6
    },
    {
      "color": {
        "a": 255,
        "b": 201,
        "g": 201,
        "r": 201
      },
      "x": 7,
      "y": 3,
      "z": 9
    },
    {
      "color": {
        "a": 255,
        "b": 201,
        "g": 201,
        "r": 201
      },
      "x": 5,
      "y": 8,
      "z": 6
    },
    {
      "color": {
        "a": 255,
        "b": 201,
        "g": 201,
        "r": 201
      },
      "x": 5,
      "y": 3,
      "z": 9
    },
    {
      "color": {
        "a": 255,
        "b": 193,
        "g": 193,
        "r": 193
      },
      "x": 11,
      "y": 6,
      "z": 10
    },
    {
      "color": {
        "a": 255,
        "b": 201,
        "g": 201,
        "r": 201
      },
      "x": 5,
      "y": 3,
      "z": 8
    },
    {
      "color": {
        "a": 255,
        "b": 201,
        "g": 201,
        "r": 201
      },
      "x": 7,
      "y": 3,
      "z": 8
    },
    {
      "color": {
        "a": 255,
        "b": 201,
        "g": 201,
        "r": 201
      },
      "x": 5,
      "y": 3,
      "z": 7
    },
    {
      "color": {
        "a": 255,
        "b": 201,
        "g": 201,
        "r": 201
      },
      "x": 9,
      "y": 3,
      "z": 8
    },
    {
      "color": {
        "a": 255,
        "b": 201,
        "g": 201,
        "r": 201
      },
      "x": 10,
      "y": 3,
      "z": 8
    },
    {
      "color": {
        "a": 255,
        "b": 201,
        "g": 201,
        "r": 201
      },
      "x": 10,
      "y": 3,
      "z": 7
    },
    {
      "color": {
        "a": 255,
        "b": 201,
        "g": 201,
        "r": 201
      },
      "x": 9,
      "y": 3,
      "z": 7
    },
    {
      "color": {
        "a": 255,
        "b": 201,
        "g": 201,
        "r": 201
      },
      "x": 7,
      "y": 3,
      "z": 7
    },
    {
      "color": {
        "a": 255,
        "b": 201,
        "g": 201,
        "r": 201
      },
      "x": 5,
      "y": 4,
      "z": 6
    },
    {
      "color": {
        "a": 255,
        "b": 201,
        "g": 201,
        "r": 201
      },
      "x": 6,
      "y": 4,
      "z": 6
    },
    {
      "color": {
        "a": 255,
        "b": 201,
        "g": 201,
        "r": 201
      },
      "x": 7,
      "y": 4,
      "z": 6
    },
    {
      "color": {
        "a": 255,
        "b": 201,
        "g": 201,
        "r": 201
      },
      "x": 8,
      "y": 4,
      "z": 6
    },
    {
      "color": {
        "a": 255,
        "b": 201,
        "g": 201,
        "r": 201
      },
      "x": 9,
      "y": 4,
      "z": 6
    },
    {
      "color": {
        "a": 255,
        "b": 201,
        "g": 201,
        "r": 201
      },
      "x": 10,
      "y": 4,
      "z": 6
    },
    {
      "color": {
        "a": 255,
        "b": 201,
        "g": 201,
        "r": 201
      },
      "x": 10,
      "y": 5,
      "z": 6
    },
    {
      "color": {
        "a": 255,
        "b": 201,
        "g": 201,
        "r": 201
      },
      "x": 9,
      "y": 5,
      "z": 6
    },
    {
      "color": {
        "a": 255,
        "b": 201,
        "g": 201,
        "r": 201
      },
      "x": 7,
      "y": 5,
      "z": 6
    },
    {
      "color": {
        "a": 255,
        "b": 201,
        "g": 201,
        "r": 201
      },
      "x": 10,
      "y": 6,
      "z": 6
    },
    {
      "color": {
        "a": 255,
        "b": 201,
        "g": 201,
        "r": 201
      },
      "x": 10,
      "y": 7,
      "z": 6
    },
    {
      "color": {
        "a": 255,
        "b": 201,
        "g": 201,
        "r": 201
      },
      "x": 9,
      "y": 7,
      "z": 6
    },
    {
      "color": {
        "a": 255,
        "b": 193,
        "g": 193,
        "r": 193
      },
      "x": 7,
      "y": 9,
      "z": 6
    },
    {
      "color": {
        "a": 255,
        "b": 201,
        "g": 201,
        "r": 201
      },
      "x": 7,
      "y": 6,
      "z": 6
    },
    {
      "color": {
        "a": 255,
        "b": 201,
        "g": 201,
        "r": 201
      },
      "x": 7,
      "y": 7,
      "z": 6
    },
    {
      "color": {
        "a": 255,
        "b": 193,
        "g": 193,
        "r": 193
      },
      "x": 9,
      "y": 9,
      "z": 6
    },
    {
      "color": {
        "a": 255,
        "b": 201,
        "g": 201,
        "r": 201
      },
      "x": 5,
      "y": 7,
      "z": 6
    },
    {
      "color": {
        "a": 255,
        "b": 193,
        "g": 193,
        "r": 193
      },
      "x": 11,
      "y": 5,
      "z": 10
    },
    {
      "color": {
        "a": 255,
        "b": 201,
        "g": 201,
        "r": 201
      },
      "x": 5,
      "y": 6,
      "z": 6
    },
    {
      "color": {
        "a": 255,
        "b": 193,
        "g": 193,
        "r": 193
      },
      "x": 11,
      "y": 8,
      "z": 10
    },
    {
      "color": {
        "a": 255,
        "b": 201,
        "g": 201,
        "r": 201
      },
      "x": 5,
      "y": 5,
      "z": 6
    },
    {
      "color": {
        "a": 255,
        "b": 193,
        "g": 193,
        "r": 193
      },
      "x": 11,
      "y": 7,
      "z": 10
    },
    {
      "color": {
        "a": 255,
        "b": 193,
        "g": 193,
        "r": 193
      },
      "x": 4,
      "y": 5,
      "z": 10
    },
    {
      "color": {
        "a": 255,
        "b": 123,
        "g": 123,
        "r": 126
      },
      "x": 6,
      "y": 6,
      "z": 11
    },
    {
      "color": {
        "a": 255,
        "b": 123,
        "g": 123,
        "r": 126
      },
      "x": 9,
      "y": 6,
      "z": 11
    },
    {
      "color": {
        "a": 255,
        "b": 193,
        "g": 193,
        "r": 193
      },
      "x": 8,
      "y": 7,
      "z": 5
    },
    {
      "color": {
        "a": 255,
        "b": 193,
        "g": 193,
        "r": 193
      },
      "x": 7,
      "y": 2,
      "z": 11
    },
    {
      "color": {
        "a": 255,
        "b": 193,
        "g": 193,
        "r": 193
      },
      "x": 10,
      "y": 7,
      "z": 5
    },
    {
      "color": {
        "a": 255,
        "b": 193,
        "g": 193,
        "r": 193
      },
      "x": 8,
      "y": 2,
      "z": 11
    },
    {
      "color": {
        "a": 255,
        "b": 193,
        "g": 193,
        "r": 193
      },
      "x": 9,
      "y": 2,
      "z": 11
    },
    {
      "color": {
        "a": 255,
        "b": 193,
        "g": 193,
        "r": 193
      },
      "x": 10,
      "y": 9,
      "z": 5
    },
    {
      "color": {
        "a": 255,
        "b": 193,
        "g": 193,
        "r": 193
      },
      "x": 6,
      "y": 2,
      "z": 11
    },
    {
      "color": {
        "a": 255,
        "b": 193,
        "g": 193,
        "r": 193
      },
      "x": 10,
      "y": 3,
      "z": 10
    },
    {
      "color": {
        "a": 255,
        "b": 193,
        "g": 193,
        "r": 193
      },
      "x": 5,
      "y": 3,
      "z": 10
    },
    {
      "color": {
        "a": 255,
        "b": 193,
        "g": 193,
        "r": 193
      },
      "x": 11,
      "y": 6,
      "z": 9
    },
    {
      "color": {
        "a": 255,
        "b": 193,
        "g": 193,
        "r": 193
      },
      "x": 6,
      "y": 9,
      "z": 5
    },
    {
      "color": {
        "a": 255,
        "b": 193,
        "g": 193,
        "r": 193
      },
      "x": 5,
      "y": 4,
      "z": 10
    },
    {
      "color": {
        "a": 255,
        "b": 193,
        "g": 193,
        "r": 193
      },
      "x": 4,
      "y": 4,
      "z": 10
    },
    {
      "color": {
        "a": 255,
        "b": 193,
        "g": 193,
        "r": 193
      },
      "x": 11,
      "y": 4,
      "z": 10
    },
    {
      "color": {
        "a": 255,
        "b": 123,
        "g": 123,
        "r": 126
      },
      "x": 6,
      "y": 6,
      "z": 10
    },
    {
      "color": {
        "a": 255,
        "b": 93,
        "g": 93,
        "r": 93
      },
      "x": 9,
      "y": 7,
      "z": 11
    },
    {
      "color": {
        "a": 255,
        "b": 180,
        "g": 180,
        "r": 180
      },
      "x": 8,
      "y": 6,
      "z": 5
    },
    {
      "color": {
        "a": 255,
        "b": 93,
        "g": 93,
        "r": 93
      },
      "x": 10,
      "y": 7,
      "z": 11
    },
    {
      "color": {
        "a": 255,
        "b": 180,
        "g": 180,
        "r": 180
      },
      "x": 7,
      "y": 2,
      "z": 5
    },
    {
      "color": {
        "a": 255,
        "b": 201,
        "g": 201,
        "r": 201
      },
      "x": 6,
      "y": 8,
      "z": 10
    },
    {
      "color": {
        "a": 255,
        "b": 193,
        "g": 193,
        "r": 193
      },
      "x": 6,
      "y": 9,
      "z": 10
    },
    {
      "color": {
        "a": 255,
        "b": 193,
        "g": 193,
        "r": 193
      },
      "x": 8,
      "y": 9,
      "z": 10
    },
    {
      "color": {
        "a": 255,
        "b": 193,
        "g": 193,
        "r": 193
      },
      "x": 10,
      "y": 9,
      "z": 10
    },
    {
      "color": {
        "a": 255,
        "b": 193,
        "g": 193,
        "r": 193
      },
      "x": 5,
      "y": 9,
      "z": 9
    },
    {
      "color": {
        "a": 255,
        "b": 193,
        "g": 193,
        "r": 193
      },
      "x": 6,
      "y": 9,
      "z": 9
    },
    {
      "color": {
        "a": 255,
        "b": 193,
        "g": 193,
        "r": 193
      },
      "x": 8,
      "y": 9,
      "z": 9
    },
    {
      "color": {
        "a": 255,
        "b": 193,
        "g": 193,
        "r": 193
      },
      "x": 10,
      "y": 9,
      "z": 9
    },
    {
      "color": {
        "a": 255,
        "b": 193,
        "g": 193,
        "r": 193
      },
      "x": 11,
      "y": 8,
      "z": 9
    },
    {
      "color": {
        "a": 255,
        "b": 193,
        "g": 193,
        "r": 193
      },
      "x": 11,
      "y": 7,
      "z": 9
    },
    {
      "color": {
        "a": 255,
        "b": 193,
        "g": 193,
        "r": 193
      },
      "x": 11,
      "y": 6,
      "z": 8
    },
    {
      "color": {
        "a": 255,
        "b": 193,
        "g": 193,
        "r": 193
      },
      "x": 11,
      "y": 7,
      "z": 7
    },
    {
      "color": {
        "a": 255,
        "b": 193,
        "g": 193,
        "r": 193
      },
      "x": 10,
      "y": 7,
      "z": 8
    },
    {
      "color": {
        "a": 255,
        "b": 193,
        "g": 193,
        "r": 193
      },
      "x": 11,
      "y": 7,
      "z": 8
    },
    {
      "color": {
        "a": 255,
        "b": 193,
        "g": 193,
        "r": 193
      },
      "x": 11,
      "y": 8,
      "z": 8
    },
    {
      "color": {
        "a": 255,
        "b": 193,
        "g": 193,
        "r": 193
      },
      "x": 11,
      "y": 8,
      "z": 7
    },
    {
      "color": {
        "a": 255,
        "b": 193,
        "g": 193,
        "r": 193
      },
      "x": 4,
      "y": 8,
      "z": 9
    },
    {
      "color": {
        "a": 255,
        "b": 193,
        "g": 193,
        "r": 193
      },
      "x": 4,
      "y": 8,
      "z": 8
    },
    {
      "color": {
        "a": 255,
        "b": 193,
        "g": 193,
        "r": 193
      },
      "x": 10,
      "y": 9,
      "z": 7
    },
    {
      "color": {
        "a": 255,
        "b": 193,
        "g": 193,
        "r": 193
      },
      "x": 4,
      "y": 8,
      "z": 7
    },
    {
      "color": {
        "a": 255,
        "b": 193,
        "g": 193,
        "r": 193
      },
      "x": 10,
      "y": 9,
      "z": 8
    },
    {
      "color": {
        "a": 255,
        "b": 193,
        "g": 193,
        "r": 193
      },
      "x": 4,
      "y": 6,
      "z": 9
    },
    {
      "color": {
        "a": 255,
        "b": 193,
        "g": 193,
        "r": 193
      },
      "x": 4,
      "y": 7,
      "z": 9
    },
    {
      "color": {
        "a": 255,
        "b": 193,
        "g": 193,
        "r": 193
      },
      "x": 4,
      "y": 5,
      "z": 9
    },
    {
      "color": {
        "a": 255,
        "b": 193,
        "g": 193,
        "r": 193
      },
      "x": 4,
      "y": 6,
      "z": 8
    },
    {
      "color": {
        "a": 255,
        "b": 193,
        "g": 193,
        "r": 193
      },
      "x": 4,
      "y": 8,
      "z": 6
    },
    {
      "color": {
        "a": 255,
        "b": 193,
        "g": 193,
        "r": 193
      },
      "x": 10,
      "y": 9,
      "z": 6
    },
    {
      "color": {
        "a": 255,
        "b": 193,
        "g": 193,
        "r": 193
      },
      "x": 8,
      "y": 9,
      "z": 8
    },
    {
      "color": {
        "a": 255,
        "b": 193,
        "g": 193,
        "r": 193
      },
      "x": 8,
      "y": 9,
      "z": 7
    },
    {
      "color": {
        "a": 255,
        "b": 193,
        "g": 193,
        "r": 193
      },
      "x": 8,
      "y": 9,
      "z": 6
    },
    {
      "color": {
        "a": 255,
        "b": 193,
        "g": 193,
        "r": 193
      },
      "x": 6,
      "y": 9,
      "z": 8
    },
    {
      "color": {
        "a": 255,
        "b": 193,
        "g": 193,
        "r": 193
      },
      "x": 6,
      "y": 9,
      "z": 7
    },
    {
      "color": {
        "a": 255,
        "b": 193,
        "g": 193,
        "r": 193
      },
      "x": 6,
      "y": 9,
      "z": 6
    },
    {
      "color": {
        "a": 255,
        "b": 193,
        "g": 193,
        "r": 193
      },
      "x": 5,
      "y": 9,
      "z": 8
    },
    {
      "color": {
        "a": 255,
        "b": 193,
        "g": 193,
        "r": 193
      },
      "x": 5,
      "y": 9,
      "z": 7
    },
    {
      "color": {
        "a": 255,
        "b": 193,
        "g": 193,
        "r": 193
      },
      "x": 5,
      "y": 9,
      "z": 6
    },
    {
      "color": {
        "a": 255,
        "b": 193,
        "g": 193,
        "r": 193
      },
      "x": 10,
      "y": 8,
      "z": 5
    },
    {
      "color": {
        "a": 255,
        "b": 193,
        "g": 193,
        "r": 193
      },
      "x": 7,
      "y": 8,
      "z": 5
    },
    {
      "color": {
        "a": 255,
        "b": 193,
        "g": 193,
        "r": 193
      },
      "x": 7,
      "y": 7,
      "z": 5
    },
    {
      "color": {
        "a": 255,
        "b": 193,
        "g": 193,
        "r": 193
      },
      "x": 9,
      "y": 9,
      "z": 5
    },
    {
      "color": {
        "a": 255,
        "b": 193,
        "g": 193,
        "r": 193
      },
      "x": 6,
      "y": 7,
      "z": 5
    },
    {
      "color": {
        "a": 255,
        "b": 193,
        "g": 193,
        "r": 193
      },
      "x": 5,
      "y": 8,
      "z": 5
    },
    {
      "color": {
        "a": 255,
        "b": 193,
        "g": 193,
        "r": 193
      },
      "x": 5,
      "y": 7,
      "z": 5
    },
    {
      "color": {
        "a": 255,
        "b": 193,
        "g": 193,
        "r": 193
      },
      "x": 4,
      "y": 7,
      "z": 6
    },
    {
      "color": {
        "a": 255,
        "b": 180,
        "g": 180,
        "r": 180
      },
      "x": 7,
      "y": 6,
      "z": 5
    },
    {
      "color": {
        "a": 255,
        "b": 180,
        "g": 180,
        "r": 180
      },
      "x": 8,
      "y": 4,
      "z": 5
    },
    {
      "color": {
        "a": 255,
        "b": 180,
        "g": 180,
        "r": 180
      },
      "x": 8,
      "y": 3,
      "z": 5
    },
    {
      "color": {
        "a": 255,
        "b": 180,
        "g": 180,
        "r": 180
      },
      "x": 7,
      "y": 3,
      "z": 5
    },
    {
      "color": {
        "a": 255,
        "b": 180,
        "g": 180,
        "r": 180
      },
      "x": 8,
      "y": 2,
      "z": 5
    },
    {
      "color": {
        "a": 255,
        "b": 201,
        "g": 201,
        "r": 201
      },
      "x": 6,
      "y": 4,
      "z": 10
    },
    {
      "color": {
        "a": 255,
        "b": 201,
        "g": 201,
        "r": 201
      },
      "x": 6,
      "y": 4,
      "z": 11
    },
    {
      "color": {
        "a": 255,
        "b": 201,
        "g": 201,
        "r": 201
      },
      "x": 7,
      "y": 4,
      "z": 10
    },
    {
      "color": {
        "a": 255,
        "b": 201,
        "g": 201,
        "r": 201
      },
      "x": 7,
      "y": 4,
      "z": 11
    },
    {
      "color": {
        "a": 255,
        "b": 201,
        "g": 201,
        "r": 201
      },
      "x": 8,
      "y": 4,
      "z": 10
    },
    {
      "color": {
        "a": 255,
        "b": 201,
        "g": 201,
        "r": 201
      },
      "x": 8,
      "y": 4,
      "z": 11
    },
    {
      "color": {
        "a": 255,
        "b": 201,
        "g": 201,
        "r": 201
      },
      "x": 9,
      "y": 4,
      "z": 11
    }
  ]
}
