{
  "assetId": "player",
  "attachments": [],
  "displayName": "player",
  "pivot": {
    "x": 0.0,
    "y": 0.0,
    "z": 0.0
  },
  "version": 2,
  "voxelSize": 0.0625,
  "voxels": [
    {
      "color": {
        "a": 255,
        "b": 0,
        "g": 255,
        "r": 15
      },
      "x": 8,
      "y": 0,
      "z": 8
    },
    {
      "color": {
        "a": 255,
        "b": 255,
        "g": 255,
        "r": 255
      },
      "x": 8,
      "y": 9,
      "z": 9
    },
    {
      "color": {
        "a": 255,
        "b": 0,
        "g": 255,
        "r": 15
      },
      "x": 8,
      "y": 1,
      "z": 8
    },
    {
      "color": {
        "a": 255,
        "b": 0,
        "g": 255,
        "r": 15
      },
      "x": 8,
      "y": 2,
      "z": 8
    },
    {
      "color": {
        "a": 255,
        "b": 0,
        "g": 0,
        "r": 255
      },
      "x": 8,
      "y": 11,
      "z": 5
    },
    {
      "color": {
        "a": 255,
        "b": 0,
        "g": 255,
        "r": 15
      },
      "x": 8,
      "y": 3,
      "z": 8
    },
    {
      "color": {
        "a": 255,
        "b": 0,
        "g": 0,
        "r": 255
      },
      "x": 10,
      "y": 10,
      "z": 8
    },
    {
      "color": {
        "a": 255,
        "b": 0,
        "g": 255,
        "r": 15
      },
      "x": 8,
      "y": 4,
      "z": 8
    },
    {
      "color": {
        "a": 255,
        "b": 0,
        "g": 255,
        "r": 15
      },
      "x": 6,
      "y": 6,
      "z": 8
    },
    {
      "color": {
        "a": 255,
        "b": 0,
        "g": 255,
        "r": 15
      },
      "x": 8,
      "y": 5,
      "z": 8
    },
    {
      "color": {
        "a": 255,
        "b": 0,
        "g": 0,
        "r": 255
      },
      "x": 10,
      "y": 11,
      "z": 11
    },
    {
      "color": {
        "a": 255,
        "b": 255,
        "g": 255,
        "r": 255
      },
      "x": 9,
      "y": 9,
      "z": 8
    },
    {
      "color": {
        "a": 255,
        "b": 0,
        "g": 255,
        "r": 15
      },
      "x": 8,
      "y": 6,
      "z": 8
    },
    {
      "color": {
        "a": 255,
        "b": 0,
        "g": 255,
        "r": 15
      },
      "x": 8,
      "y": 7,
      "z": 8
    },
    {
      "color": {
        "a": 255,
        "b": 0,
        "g": 0,
        "r": 255
      },
      "x": 6,
      "y": 11,
      "z": 5
    },
    {
      "color": {
        "a": 255,
        "b": 0,
        "g": 255,
        "r": 15
      },
      "x": 7,
      "y": 5,
      "z": 8
    },
    {
      "color": {
        "a": 255,
        "b": 0,
        "g": 255,
        "r": 15
      },
      "x": 8,
      "y": 8,
      "z": 8
    },
    {
      "color": {
        "a": 255,
        "b": 0,
        "g": 0,
        "r": 255
      },
      "x": 8,
      "y": 10,
      "z": 8
    },
    {
      "color": {
        "a": 255,
        "b": 0,
        "g": 0,
        "r": 255
      },
      "x": 6,
      "y": 11,
      "z": 11
    },
    {
      "color": {
        "a": 255,
        "b": 0,
        "g": 255,
        "r": 15
      },
      "x": 9,
      "y": 5,
      "z": 8
    },
    {
      "color": {
        "a": 255,
        "b": 0,
        "g": 0,
        "r": 255
      },
      "x": 8,
      "y": 11,
      "z": 11
    },
    {
      "color": {
        "a": 255,
        "b": 0,
        "g": 0,
        "r": 255
      },
      "x": 11,
      "y": 11,
      "z": 6
    },
    {
      "color": {
        "a": 255,
        "b": 0,
        "g": 0,
        "r": 255
      },
      "x": 6,
      "y": 10,
      "z": 8
    },
    {
      "color": {
        "a": 255,
        "b": 0,
        "g": 255,
        "r": 15
      },
      "x": 10,
      "y": 6,
      "z": 8
    },
    {
      "color": {
        "a": 255,
        "b": 0,
        "g": 255,
        "r": 15
      },
      "x": 8,
      "y": 5,
      "z": 9
    },
    {
      "color": {
        "a": 255,
        "b": 0,
        "g": 255,
        "r": 15
      },
      "x": 8,
      "y": 6,
      "z": 10
    },
    {
      "color": {
        "a": 255,
        "b": 0,
        "g": 0,
        "r": 255
      },
      "x": 10,
      "y": 10,
      "z": 10
    },
    {
      "color": {
        "a": 255,
        "b": 0,
        "g": 255,
        "r": 15
      },
      "x": 8,
      "y": 5,
      "z": 7
    },
    {
      "color": {
        "a": 255,
        "b": 0,
        "g": 255,
        "r": 15
      },
      "x": 8,
      "y": 6,
      "z": 6
    },
    {
      "color": {
        "a": 255,
        "b": 255,
        "g": 255,
        "r": 255
      },
      "x": 8,
      "y": 9,
      "z": 8
    },
    {
      "color": {
        "a": 255,
        "b": 0,
        "g": 0,
        "r": 255
      },
      "x": 10,
      "y": 11,
      "z": 5
    },
    {
      "color": {
        "a": 255,
        "b": 255,
        "g": 255,
        "r": 255
      },
      "x": 7,
      "y": 9,
      "z": 8
    },
    {
      "color": {
        "a": 255,
        "b": 255,
        "g": 255,
        "r": 255
      },
      "x": 7,
      "y": 9,
      "z": 9
    },
    {
      "color": {
        "a": 255,
        "b": 255,
        "g": 255,
        "r": 255
      },
      "x": 7,
      "y": 9,
      "z": 7
    },
    {
      "color": {
        "a": 255,
        "b": 0,
        "g": 0,
        "r": 255
      },
      "x": 6,
      "y": 10,
      "z": 10
    },
    {
      "color": {
        "a": 255,
        "b": 255,
        "g": 255,
        "r": 255
      },
      "x": 8,
      "y": 9,
      "z": 7
    },
    {
      "color": {
        "a": 255,
        "b": 255,
        "g": 255,
        "r": 255
      },
      "x": 9,
      "y": 9,
      "z": 7
    },
    {
      "color": {
        "a": 255,
        "b": 255,
        "g": 255,
        "r": 255
      },
      "x": 9,
      "y": 9,
      "z": 9
    },
    {
      "color": {
        "a": 255,
        "b": 0,
        "g": 0,
        "r": 255
      },
      "x": 10,
      "y": 10,
      "z": 9
    },
    {
      "color": {
        "a": 255,
        "b": 0,
        "g": 0,
        "r": 255
      },
      "x": 9,
      "y": 10,
      "z": 10
    },
    {
      "color": {
        "a": 255,
        "b": 0,
        "g": 0,
        "r": 255
      },
      "x": 10,
      "y": 10,
      "z": 7
    },
    {
      "color": {
        "a": 255,
        "b": 0,
        "g": 0,
        "r": 255
      },
      "x": 10,
      "y": 10,
      "z": 6
    },
    {
      "color": {
        "a": 255,
        "b": 0,
        "g": 0,
        "r": 255
      },
      "x": 9,
      "y": 10,
      "z": 6
    },
    {
      "color": {
        "a": 255,
        "b": 0,
        "g": 0,
        "r": 255
      },
      "x": 8,
      "y": 10,
      "z": 6
    },
    {
      "color": {
        "a": 255,
        "b": 0,
        "g": 0,
        "r": 255
      },
      "x": 6,
      "y": 10,
      "z": 9
    },
    {
      "color": {
        "a": 255,
        "b": 0,
        "g": 0,
        "r": 255
      },
      "x": 7,
      "y": 10,
      "z": 6
    },
    {
      "color": {
        "a": 255,
        "b": 0,
        "g": 0,
        "r": 255
      },
      "x": 11,
      "y": 11,
      "z": 8
    },
    {
      "color": {
        "a": 255,
        "b": 0,
        "g": 0,
        "r": 255
      },
      "x": 6,
      "y": 10,
      "z": 6
    },
    {
      "color": {
        "a": 255,
        "b": 0,
        "g": 0,
        "r": 255
      },
      "x": 6,
      "y": 10,
      "z": 7
    },
    {
      "color": {
        "a": 255,
        "b": 0,
        "g": 0,
        "r": 255
      },
      "x": 7,
      "y": 10,
      "z": 10
    },
    {
      "color": {
        "a": 255,
        "b": 0,
        "g": 0,
        "r": 255
      },
      "x": 8,
      "y": 10,
      "z": 10
    },
    {
      "color": {
        "a": 255,
        "b": 0,
        "g": 0,
        "r": 255
      },
      "x": 5,
      "y": 11,
      "z": 10
    },
    {
      "color": {
        "a": 255,
        "b": 0,
        "g": 0,
        "r": 255
      },
      "x": 11,
      "y": 11,
      "z": 10
    },
    {
      "color": {
        "a": 255,
        "b": 0,
        "g": 0,
        "r": 255
      },
      "x": 5,
      "y": 11,
      "z": 6
    },
    {
      "color": {
        "a": 255,
        "b": 0,
        "g": 0,
        "r": 255
      },
      "x": 5,
      "y": 11,
      "z": 8
    }
  ]
}
