{
  "assetId": "shoe_1",
  "attachments": [],
  "displayName": "shoe_1",
  "pivot": {
    "x": 0.53125,
    "y": 0.28125,
    "z": 0.59375
  },
  "version": 2,
  "voxelSize": 0.0625,
  "voxels": [
    {
      "color": {
        "a": 255,
        "b": 201,
        "g": 201,
        "r": 201
      },
      "x": 8,
      "y": 4,
      "z": 8
    },
    {
      "color": {
        "a": 255,
        "b": 201,
        "g": 201,
        "r": 201
      },
      "x": 8,
      "y": 4,
      "z": 9
    },
    {
      "color": {
        "a": 255,
        "b": 78,
        "g": 78,
        "r": 78
      },
      "x": 8,
      "y": 5,
      "z": 7
    },
    {
      "color": {
        "a": 255,
        "b": 201,
        "g": 201,
        "r": 201
      },
      "x": 8,
      "y": 4,
      "z": 10
    },
    {
      "color": {
        "a": 255,
        "b": 78,
        "g": 78,
        "r": 78
      },
      "x": 7,
      "y": 5,
      "z": 9
    },
    {
      "color": {
        "a": 255,
        "b": 78,
        "g": 78,
        "r": 78
      },
      "x": 7,
      "y": 3,
      "z": 11
    },
    {
      "color": {
        "a": 255,
        "b": 78,
        "g": 78,
        "r": 78
      },
      "x": 8,
      "y": 5,
      "z": 8
    },
    {
      "color": {
        "a": 255,
        "b": 78,
        "g": 78,
        "r": 78
      },
      "x": 8,
      "y": 3,
      "z": 7
    },
    {
      "color": {
        "a": 255,
        "b": 129,
        "g": 129,
        "r": 129
      },
      "x": 7,
      "y": 4,
      "z": 11
    },
    {
      "color": {
        "a": 255,
        "b": 78,
        "g": 78,
        "r": 78
      },
      "x": 9,
      "y": 5,
      "z": 7
    },
    {
      "color": {
        "a": 255,
        "b": 78,
        "g": 78,
        "r": 78
      },
      "x": 7,
      "y": 5,
      "z": 7
    },
    {
      "color": {
        "a": 255,
        "b": 78,
        "g": 78,
        "r": 78
      },
      "x": 7,
      "y": 5,
      "z": 10
    },
    {
      "color": {
        "a": 255,
        "b": 78,
        "g": 78,
        "r": 78
      },
      "x": 9,
      "y": 5,
      "z": 8
    },
    {
      "color": {
        "a": 255,
        "b": 78,
        "g": 78,
        "r": 78
      },
      "x": 7,
      "y": 5,
      "z": 8
    },
    {
      "color": {
        "a": 255,
        "b": 129,
        "g": 129,
        "r": 129
      },
      "x": 8,
      "y": 4,
      "z": 11
    },
    {
      "color": {
        "a": 255,
        "b": 129,
        "g": 129,
        "r": 129
      },
      "x": 9,
      "y": 4,
      "z": 11
    },
    {
      "color": {
        "a": 255,
        "b": 78,
        "g": 78,
        "r": 78
      },
      "x": 8,
      "y": 3,
      "z": 11
    },
    {
      "color": {
        "a": 255,
        "b": 78,
        "g": 78,
        "r": 78
      },
      "x": 9,
      "y": 3,
      "z": 10
    },
    {
      "color": {
        "a": 255,
        "b": 78,
        "g": 78,
        "r": 78
      },
      "x": 9,
      "y": 3,
      "z": 11
    },
    {
      "color": {
        "a": 255,
        "b": 78,
        "g": 78,
        "r": 78
      },
      "x": 9,
      "y": 3,
      "z": 9
    },
    {
      "color": {
        "a": 255,
        "b": 78,
        "g": 78,
        "r": 78
      },
      "x": 9,
      "y": 3,
      "z": 8
    },
    {
      "color": {
        "a": 255,
        "b": 78,
        "g": 78,
        "r": 78
      },
      "x": 9,
      "y": 3,
      "z": 7
    },
    {
      "color": {
        "a": 255,
        "b": 78,
        "g": 78,
        "r": 78
      },
      "x": 8,
      "y": 3,
      "z": 10
    },
    {
      "color": {
        "a": 255,
        "b": 78,
        "g": 78,
        "r": 78
      },
      "x": 8,
      "y": 3,
      "z": 9
    },
    {
      "color": {
        "a": 255,
        "b": 78,
        "g": 78,
        "r": 78
      },
      "x": 8,
      "y": 3,
      "z": 8
    },
    {
      "color": {
        "a": 255,
        "b": 78,
        "g": 78,
        "r": 78
      },
      "x": 7,
      "y": 3,
      "z": 10
    },
    {
      "color": {
        "a": 255,
        "b": 78,
        "g": 78,
        "r": 78
      },
      "x": 7,
      "y": 3,
      "z": 9
    },
    {
      "color": {
        "a": 255,
        "b": 78,
        "g": 78,
        "r": 78
      },
      "x": 7,
      "y": 3,
      "z": 8
    },
    {
      "color": {
        "a": 255,
        "b": 78,
        "g": 78,
        "r": 78
      },
      "x": 7,
      "y": 3,
      "z": 7
    },
    {
      "color": {
        "a": 255,
        "b": 78,
        "g": 78,
        "r": 78
      },
      "x": 8,
      "y": 5,
      "z": 10
    },
    {
      "color": {
        "a": 255,
        "b": 78,
        "g": 78,
        "r": 78
      },
      "x": 8,
      "y": 5,
      "z": 9
    },
    {
      "color": {
        "a": 255,
        "b": 78,
        "g": 78,
        "r": 78
      },
      "x": 9,
      "y": 5,
      "z": 9
    },
    {
      "color": {
        "a": 255,
        "b": 78,
        "g": 78,
        "r": 78
      },
      "x": 9,
      "y": 5,
      "z": 10
    },
    {
      "color": {
        "a": 255,
        "b": 78,
        "g": 78,
        "r": 78
      },
      "x": 9,
      "y": 4,
      "z": 10
    },
    {
      "color": {
        "a": 255,
        "b": 78,
        "g": 78,
        "r": 78
      },
      "x": 9,
      "y": 4,
      "z": 9
    },
    {
      "color": {
        "a": 255,
        "b": 78,
        "g": 78,
        "r": 78
      },
      "x": 9,
      "y": 4,
      "z": 8
    },
    {
      "color": {
        "a": 255,
        "b": 78,
        "g": 78,
        "r": 78
      },
      "x": 9,
      "y": 4,
      "z": 7
    },
    {
      "color": {
        "a": 255,
        "b": 78,
        "g": 78,
        "r": 78
      },
      "x": 8,
      "y": 4,
      "z": 7
    },
    {
      "color": {
        "a": 255,
        "b": 78,
        "g": 78,
        "r": 78
      },
      "x": 7,
      "y": 4,
      "z": 7
    },
    {
      "color": {
        "a": 255,
        "b": 78,
        "g": 78,
        "r": 78
      },
      "x": 7,
      "y": 4,
      "z": 8
    },
    {
      "color": {
        "a": 255,
        "b": 78,
        "g": 78,
        "r": 78
      },
      "x": 7,
      "y": 4,
      "z": 9
    },
    {
      "color": {
        "a": 255,
        "b": 78,
        "g": 78,
        "r": 78
      },
      "x": 7,
      "y": 4,
      "z": 10
    }
  ]
}
