{
  "assetId": "simple_block",
  "attachments": [],
  "displayName": "simple_block",
  "pivot": {
    "x": 0.5,
    "y": 0.375,
    "z": 0.5625
  },
  "version": 2,
  "voxelSize": 0.0625,
  "voxels": [
    {
      "color": {
        "a": 255,
        "b": 201,
        "g": 201,
        "r": 201
      },
      "x": 5,
      "y": 8,
      "z": 7
    },
    {
      "color": {
        "a": 255,
        "b": 201,
        "g": 201,
        "r": 201
      },
      "x": 8,
      "y": 8,
      "z": 8
    },
    {
      "color": {
        "a": 255,
        "b": 201,
        "g": 201,
        "r": 201
      },
      "x": 6,
      "y": 8,
      "z": 11
    },
    {
      "color": {
        "a": 255,
        "b": 201,
        "g": 201,
        "r": 201
      },
      "x": 7,
      "y": 8,
      "z": 8
    },
    {
      "color": {
        "a": 255,
        "b": 201,
        "g": 201,
        "r": 201
      },
      "x": 8,
      "y": 8,
      "z": 9
    },
    {
      "color": {
        "a": 255,
        "b": 201,
        "g": 201,
        "r": 201
      },
      "x": 8,
      "y": 3,
      "z": 6
    },
    {
      "color": {
        "a": 255,
        "b": 201,
        "g": 201,
        "r": 201
      },
      "x": 6,
      "y": 5,
      "z": 6
    },
    {
      "color": {
        "a": 255,
        "b": 201,
        "g": 201,
        "r": 201
      },
      "x": 7,
      "y": 8,
      "z": 9
    },
    {
      "color": {
        "a": 255,
        "b": 201,
        "g": 201,
        "r": 201
      },
      "x": 7,
      "y": 3,
      "z": 6
    },
    {
      "color": {
        "a": 255,
        "b": 201,
        "g": 201,
        "r": 201
      },
      "x": 5,
      "y": 7,
      "z": 10
    },
    {
      "color": {
        "a": 255,
        "b": 201,
        "g": 201,
        "r": 201
      },
      "x": 7,
      "y": 8,
      "z": 11
    },
    {
      "color": {
        "a": 255,
        "b": 201,
        "g": 201,
        "r": 201
      },
      "x": 6,
      "y": 8,
      "z": 8
    },
    {
      "color": {
        "a": 255,
        "b": 201,
        "g": 201,
        "r": 201
      },
      "x": 6,
      "y": 8,
      "z": 9
    },
    {
      "color": {
        "a": 255,
        "b": 201,
        "g": 201,
        "r": 201
      },
      "x": 6,
      "y": 3,
      "z": 6
    },
    {
      "color": {
        "a": 255,
        "b": 201,
        "g": 201,
        "r": 201
      },
      "x": 8,
      "y": 5,
      "z": 6
    },
    {
      "color": {
        "a": 255,
        "b": 201,
        "g": 201,
        "r": 201
      },
      "x": 6,
      "y": 7,
      "z": 10
    },
    {
      "color": {
        "a": 255,
        "b": 201,
        "g": 201,
        "r": 201
      },
      "x": 8,
      "y": 8,
      "z": 7
    },
    {
      "color": {
        "a": 255,
        "b": 201,
        "g": 201,
        "r": 201
      },
      "x": 5,
      "y": 8,
      "z": 8
    },
    {
      "color": {
        "a": 255,
        "b": 201,
        "g": 201,
        "r": 201
      },
      "x": 5,
      "y": 8,
      "z": 9
    },
    {
      "color": {
        "a": 255,
        "b": 201,
        "g": 201,
        "r": 201
      },
      "x": 5,
      "y": 3,
      "z": 6
    },
    {
      "color": {
        "a": 255,
        "b": 201,
        "g": 201,
        "r": 201
      },
      "x": 7,
      "y": 7,
      "z": 10
    },
    {
      "color": {
        "a": 255,
        "b": 201,
        "g": 201,
        "r": 201
      },
      "x": 5,
      "y": 8,
      "z": 11
    },
    {
      "color": {
        "a": 255,
        "b": 201,
        "g": 201,
        "r": 201
      },
      "x": 8,
      "y": 7,
      "z": 10
    },
    {
      "color": {
        "a": 255,
        "b": 201,
        "g": 201,
        "r": 201
      },
      "x": 6,
      "y": 8,
      "z": 7
    },
    {
      "color": {
        "a": 255,
        "b": 201,
        "g": 201,
        "r": 201
      },
      "x": 9,
      "y": 8,
      "z": 9
    },
    {
      "color": {
        "a": 255,
        "b": 201,
        "g": 201,
        "r": 201
      },
      "x": 9,
      "y": 3,
      "z": 6
    },
    {
      "color": {
        "a": 255,
        "b": 201,
        "g": 201,
        "r": 201
      },
      "x": 9,
      "y": 8,
      "z": 8
    },
    {
      "color": {
        "a": 255,
        "b": 201,
        "g": 201,
        "r": 201
      },
      "x": 10,
      "y": 8,
      "z": 9
    },
    {
      "color": {
        "a": 255,
        "b": 201,
        "g": 201,
        "r": 201
      },
      "x": 10,
      "y": 3,
      "z": 6
    },
    {
      "color": {
        "a": 255,
        "b": 201,
        "g": 201,
        "r": 201
      },
      "x": 10,
      "y": 8,
      "z": 8
    },
    {
      "color": {
        "a": 255,
        "b": 201,
        "g": 201,
        "r": 201
      },
      "x": 8,
      "y": 7,
      "z": 7
    },
    {
      "color": {
        "a": 255,
        "b": 201,
        "g": 201,
        "r": 201
      },
      "x": 5,
      "y": 7,
      "z": 8
    },
    {
      "color": {
        "a": 255,
        "b": 201,
        "g": 201,
        "r": 201
      },
      "x": 6,
      "y": 8,
      "z": 10
    },
    {
      "color": {
        "a": 255,
        "b": 201,
        "g": 201,
        "r": 201
      },
      "x": 5,
      "y": 7,
      "z": 11
    },
    {
      "color": {
        "a": 255,
        "b": 201,
        "g": 201,
        "r": 201
      },
      "x": 7,
      "y": 8,
      "z": 10
    },
    {
      "color": {
        "a": 255,
        "b": 201,
        "g": 201,
        "r": 201
      },
      "x": 6,
      "y": 7,
      "z": 8
    },
    {
      "color": {
        "a": 255,
        "b": 201,
        "g": 201,
        "r": 201
      },
      "x": 7,
      "y": 7,
      "z": 11
    },
    {
      "color": {
        "a": 255,
        "b": 201,
        "g": 201,
        "r": 201
      },
      "x": 5,
      "y": 8,
      "z": 10
    },
    {
      "color": {
        "a": 255,
        "b": 201,
        "g": 201,
        "r": 201
      },
      "x": 6,
      "y": 7,
      "z": 7
    },
    {
      "color": {
        "a": 255,
        "b": 201,
        "g": 201,
        "r": 201
      },
      "x": 8,
      "y": 8,
      "z": 10
    },
    {
      "color": {
        "a": 255,
        "b": 201,
        "g": 201,
        "r": 201
      },
      "x": 10,
      "y": 8,
      "z": 7
    },
    {
      "color": {
        "a": 255,
        "b": 201,
        "g": 201,
        "r": 201
      },
      "x": 9,
      "y": 8,
      "z": 10
    },
    {
      "color": {
        "a": 255,
        "b": 201,
        "g": 201,
        "r": 201
      },
      "x": 9,
      "y": 8,
      "z": 7
    },
    {
      "color": {
        "a": 255,
        "b": 201,
        "g": 201,
        "r": 201
      },
      "x": 10,
      "y": 8,
      "z": 10
    },
    {
      "color": {
        "a": 255,
        "b": 201,
        "g": 201,
        "r": 201
      },
      "x": 7,
      "y": 8,
      "z": 7
    },
    {
      "color": {
        "a": 255,
        "b": 201,
        "g": 201,
        "r": 201
      },
      "x": 8,
      "y": 8,
      "z": 11
    },
    {
      "color": {
        "a": 255,
        "b": 201,
        "g": 201,
        "r": 201
      },
      "x": 9,
      "y": 8,
      "z": 11
    },
    {
      "color": {
        "a": 255,
        "b": 201,
        "g": 201,
        "r": 201
      },
      "x": 10,
      "y": 8,
      "z": 11
    },
    {
      "color": {
        "a": 255,
        "b": 201,
        "g": 201,
        "r": 201
      },
      "x": 7,
      "y": 7,
      "z": 8
    },
    {
      "color": {
        "a": 255,
        "b": 201,
        "g": 201,
        "r": 201
      },
      "x": 6,
      "y": 7,
      "z": 11
    },
    {
      "color": {
        "a": 255,
        "b": 201,
        "g": 201,
        "r": 201
      },
      "x": 8,
      "y": 7,
      "z": 11
    },
    {
      "color": {
        "a": 255,
        "b": 201,
        "g": 201,
        "r": 201
      },
      "x": 9,
      "y": 7,
      "z": 11
    },
    {
      "color": {
        "a": 255,
        "b": 201,
        "g": 201,
        "r": 201
      },
      "x": 10,
      "y": 7,
      "z": 11
    },
    {
      "color": {
        "a": 255,
        "b": 201,
        "g": 201,
        "r": 201
      },
      "x": 5,
      "y": 7,
      "z": 7
    },
    {
      "color": {
        "a": 255,
        "b": 201,
        "g": 201,
        "r": 201
      },
      "x": 8,
      "y": 7,
      "z": 8
    },
    {
      "color": {
        "a": 255,
        "b": 201,
        "g": 201,
        "r": 201
      },
      "x": 10,
      "y": 7,
      "z": 9
    },
    {
      "color": {
        "a": 255,
        "b": 201,
        "g": 201,
        "r": 201
      },
      "x": 9,
      "y": 7,
      "z": 9
    },
    {
      "color": {
        "a": 255,
        "b": 201,
        "g": 201,
        "r": 201
      },
      "x": 10,
      "y": 7,
      "z": 7
    },
    {
      "color": {
        "a": 255,
        "b": 201,
        "g": 201,
        "r": 201
      },
      "x": 9,
      "y": 7,
      "z": 10
    },
    {
      "color": {
        "a": 255,
        "b": 201,
        "g": 201,
        "r": 201
      },
      "x": 6,
      "y": 7,
      "z": 9
    },
    {
      "color": {
        "a": 255,
        "b": 201,
        "g": 201,
        "r": 201
      },
      "x": 8,
      "y": 6,
      "z": 6
    },
    {
      "color": {
        "a": 255,
        "b": 201,
        "g": 201,
        "r": 201
      },
      "x": 5,
      "y": 7,
      "z": 9
    },
    {
      "color": {
        "a": 255,
        "b": 201,
        "g": 201,
        "r": 201
      },
      "x": 7,
      "y": 7,
      "z": 9
    },
    {
      "color": {
        "a": 255,
        "b": 201,
        "g": 201,
        "r": 201
      },
      "x": 8,
      "y": 7,
      "z": 9
    },
    {
      "color": {
        "a": 255,
        "b": 201,
        "g": 201,
        "r": 201
      },
      "x": 6,
      "y": 6,
      "z": 6
    },
    {
      "color": {
        "a": 255,
        "b": 201,
        "g": 201,
        "r": 201
      },
      "x": 9,
      "y": 7,
      "z": 7
    },
    {
      "color": {
        "a": 255,
        "b": 201,
        "g": 201,
        "r": 201
      },
      "x": 10,
      "y": 7,
      "z": 10
    },
    {
      "color": {
        "a": 255,
        "b": 201,
        "g": 201,
        "r": 201
      },
      "x": 7,
      "y": 7,
      "z": 7
    },
    {
      "color": {
        "a": 255,
        "b": 201,
        "g": 201,
        "r": 201
      },
      "x": 9,
      "y": 7,
      "z": 8
    },
    {
      "color": {
        "a": 255,
        "b": 201,
        "g": 201,
        "r": 201
      },
      "x": 10,
      "y": 7,
      "z": 8
    },
    {
      "color": {
        "a": 255,
        "b": 201,
        "g": 201,
        "r": 201
      },
      "x": 5,
      "y": 6,
      "z": 11
    },
    {
      "color": {
        "a": 255,
        "b": 201,
        "g": 201,
        "r": 201
      },
      "x": 7,
      "y": 5,
      "z": 10
    },
    {
      "color": {
        "a": 255,
        "b": 201,
        "g": 201,
        "r": 201
      },
      "x": 5,
      "y": 6,
      "z": 10
    },
    {
      "color": {
        "a": 255,
        "b": 201,
        "g": 201,
        "r": 201
      },
      "x": 7,
      "y": 5,
      "z": 11
    },
    {
      "color": {
        "a": 255,
        "b": 201,
        "g": 201,
        "r": 201
      },
      "x": 5,
      "y": 6,
      "z": 9
    },
    {
      "color": {
        "a": 255,
        "b": 201,
        "g": 201,
        "r": 201
      },
      "x": 5,
      "y": 6,
      "z": 8
    },
    {
      "color": {
        "a": 255,
        "b": 201,
        "g": 201,
        "r": 201
      },
      "x": 5,
      "y": 6,
      "z": 7
    },
    {
      "color": {
        "a": 255,
        "b": 201,
        "g": 201,
        "r": 201
      },
      "x": 6,
      "y": 6,
      "z": 7
    },
    {
      "color": {
        "a": 255,
        "b": 201,
        "g": 201,
        "r": 201
      },
      "x": 6,
      "y": 6,
      "z": 8
    },
    {
      "color": {
        "a": 255,
        "b": 201,
        "g": 201,
        "r": 201
      },
      "x": 6,
      "y": 6,
      "z": 9
    },
    {
      "color": {
        "a": 255,
        "b": 201,
        "g": 201,
        "r": 201
      },
      "x": 8,
      "y": 7,
      "z": 6
    },
    {
      "color": {
        "a": 255,
        "b": 201,
        "g": 201,
        "r": 201
      },
      "x": 6,
      "y": 6,
      "z": 10
    },
    {
      "color": {
        "a": 255,
        "b": 201,
        "g": 201,
        "r": 201
      },
      "x": 6,
      "y": 6,
      "z": 11
    },
    {
      "color": {
        "a": 255,
        "b": 201,
        "g": 201,
        "r": 201
      },
      "x": 7,
      "y": 6,
      "z": 11
    },
    {
      "color": {
        "a": 255,
        "b": 201,
        "g": 201,
        "r": 201
      },
      "x": 5,
      "y": 5,
      "z": 10
    },
    {
      "color": {
        "a": 255,
        "b": 201,
        "g": 201,
        "r": 201
      },
      "x": 7,
      "y": 6,
      "z": 10
    },
    {
      "color": {
        "a": 255,
        "b": 201,
        "g": 201,
        "r": 201
      },
      "x": 5,
      "y": 5,
      "z": 11
    },
    {
      "color": {
        "a": 255,
        "b": 201,
        "g": 201,
        "r": 201
      },
      "x": 7,
      "y": 6,
      "z": 9
    },
    {
      "color": {
        "a": 255,
        "b": 201,
        "g": 201,
        "r": 201
      },
      "x": 7,
      "y": 6,
      "z": 8
    },
    {
      "color": {
        "a": 255,
        "b": 201,
        "g": 201,
        "r": 201
      },
      "x": 8,
      "y": 6,
      "z": 8
    },
    {
      "color": {
        "a": 255,
        "b": 201,
        "g": 201,
        "r": 201
      },
      "x": 8,
      "y": 6,
      "z": 9
    },
    {
      "color": {
        "a": 255,
        "b": 201,
        "g": 201,
        "r": 201
      },
      "x": 6,
      "y": 7,
      "z": 6
    },
    {
      "color": {
        "a": 255,
        "b": 201,
        "g": 201,
        "r": 201
      },
      "x": 8,
      "y": 6,
      "z": 10
    },
    {
      "color": {
        "a": 255,
        "b": 201,
        "g": 201,
        "r": 201
      },
      "x": 8,
      "y": 6,
      "z": 11
    },
    {
      "color": {
        "a": 255,
        "b": 201,
        "g": 201,
        "r": 201
      },
      "x": 9,
      "y": 6,
      "z": 11
    },
    {
      "color": {
        "a": 255,
        "b": 201,
        "g": 201,
        "r": 201
      },
      "x": 9,
      "y": 6,
      "z": 10
    },
    {
      "color": {
        "a": 255,
        "b": 201,
        "g": 201,
        "r": 201
      },
      "x": 9,
      "y": 6,
      "z": 9
    },
    {
      "color": {
        "a": 255,
        "b": 201,
        "g": 201,
        "r": 201
      },
      "x": 9,
      "y": 6,
      "z": 8
    },
    {
      "color": {
        "a": 255,
        "b": 201,
        "g": 201,
        "r": 201
      },
      "x": 10,
      "y": 6,
      "z": 9
    },
    {
      "color": {
        "a": 255,
        "b": 201,
        "g": 201,
        "r": 201
      },
      "x": 10,
      "y": 6,
      "z": 10
    },
    {
      "color": {
        "a": 255,
        "b": 201,
        "g": 201,
        "r": 201
      },
      "x": 10,
      "y": 6,
      "z": 11
    },
    {
      "color": {
        "a": 255,
        "b": 201,
        "g": 201,
        "r": 201
      },
      "x": 10,
      "y": 6,
      "z": 8
    },
    {
      "color": {
        "a": 255,
        "b": 201,
        "g": 201,
        "r": 201
      },
      "x": 10,
      "y": 6,
      "z": 7
    },
    {
      "color": {
        "a": 255,
        "b": 201,
        "g": 201,
        "r": 201
      },
      "x": 9,
      "y": 6,
      "z": 7
    },
    {
      "color": {
        "a": 255,
        "b": 201,
        "g": 201,
        "r": 201
      },
      "x": 8,
      "y": 6,
      "z": 7
    },
    {
      "color": {
        "a": 255,
        "b": 201,
        "g": 201,
        "r": 201
      },
      "x": 7,
      "y": 6,
      "z": 7
    },
    {
      "color": {
        "a": 255,
        "b": 201,
        "g": 201,
        "r": 201
      },
      "x": 5,
      "y": 5,
      "z": 9
    },
    {
      "color": {
        "a": 255,
        "b": 201,
        "g": 201,
        "r": 201
      },
      "x": 6,
      "y": 5,
      "z": 9
    },
    {
      "color": {
        "a": 255,
        "b": 201,
        "g": 201,
        "r": 201
      },
      "x": 8,
      "y": 3,
      "z": 9
    },
    {
      "color": {
        "a": 255,
        "b": 201,
        "g": 201,
        "r": 201
      },
      "x": 8,
      "y": 8,
      "z": 6
    },
    {
      "color": {
        "a": 255,
        "b": 201,
        "g": 201,
        "r": 201
      },
      "x": 6,
      "y": 5,
      "z": 10
    },
    {
      "color": {
        "a": 255,
        "b": 201,
        "g": 201,
        "r": 201
      },
      "x": 8,
      "y": 3,
      "z": 10
    },
    {
      "color": {
        "a": 255,
        "b": 201,
        "g": 201,
        "r": 201
      },
      "x": 6,
      "y": 5,
      "z": 11
    },
    {
      "color": {
        "a": 255,
        "b": 201,
        "g": 201,
        "r": 201
      },
      "x": 8,
      "y": 3,
      "z": 11
    },
    {
      "color": {
        "a": 255,
        "b": 201,
        "g": 201,
        "r": 201
      },
      "x": 8,
      "y": 5,
      "z": 11
    },
    {
      "color": {
        "a": 255,
        "b": 201,
        "g": 201,
        "r": 201
      },
      "x": 6,
      "y": 3,
      "z": 11
    },
    {
      "color": {
        "a": 255,
        "b": 201,
        "g": 201,
        "r": 201
      },
      "x": 8,
      "y": 5,
      "z": 10
    },
    {
      "color": {
        "a": 255,
        "b": 201,
        "g": 201,
        "r": 201
      },
      "x": 6,
      "y": 3,
      "z": 10
    },
    {
      "color": {
        "a": 255,
        "b": 201,
        "g": 201,
        "r": 201
      },
      "x": 8,
      "y": 5,
      "z": 9
    },
    {
      "color": {
        "a": 255,
        "b": 201,
        "g": 201,
        "r": 201
      },
      "x": 6,
      "y": 3,
      "z": 9
    },
    {
      "color": {
        "a": 255,
        "b": 201,
        "g": 201,
        "r": 201
      },
      "x": 6,
      "y": 8,
      "z": 6
    },
    {
      "color": {
        "a": 255,
        "b": 201,
        "g": 201,
        "r": 201
      },
      "x": 7,
      "y": 5,
      "z": 9
    },
    {
      "color": {
        "a": 255,
        "b": 201,
        "g": 201,
        "r": 201
      },
      "x": 9,
      "y": 5,
      "z": 10
    },
    {
      "color": {
        "a": 255,
        "b": 201,
        "g": 201,
        "r": 201
      },
      "x": 9,
      "y": 5,
      "z": 11
    },
    {
      "color": {
        "a": 255,
        "b": 201,
        "g": 201,
        "r": 201
      },
      "x": 10,
      "y": 5,
      "z": 11
    },
    {
      "color": {
        "a": 255,
        "b": 201,
        "g": 201,
        "r": 201
      },
      "x": 10,
      "y": 5,
      "z": 10
    },
    {
      "color": {
        "a": 255,
        "b": 201,
        "g": 201,
        "r": 201
      },
      "x": 10,
      "y": 5,
      "z": 9
    },
    {
      "color": {
        "a": 255,
        "b": 201,
        "g": 201,
        "r": 201
      },
      "x": 10,
      "y": 5,
      "z": 8
    },
    {
      "color": {
        "a": 255,
        "b": 201,
        "g": 201,
        "r": 201
      },
      "x": 9,
      "y": 5,
      "z": 8
    },
    {
      "color": {
        "a": 255,
        "b": 201,
        "g": 201,
        "r": 201
      },
      "x": 8,
      "y": 5,
      "z": 8
    },
    {
      "color": {
        "a": 255,
        "b": 201,
        "g": 201,
        "r": 201
      },
      "x": 6,
      "y": 3,
      "z": 8
    },
    {
      "color": {
        "a": 255,
        "b": 201,
        "g": 201,
        "r": 201
      },
      "x": 7,
      "y": 5,
      "z": 8
    },
    {
      "color": {
        "a": 255,
        "b": 201,
        "g": 201,
        "r": 201
      },
      "x": 6,
      "y": 5,
      "z": 8
    },
    {
      "color": {
        "a": 255,
        "b": 201,
        "g": 201,
        "r": 201
      },
      "x": 8,
      "y": 3,
      "z": 8
    },
    {
      "color": {
        "a": 255,
        "b": 201,
        "g": 201,
        "r": 201
      },
      "x": 5,
      "y": 5,
      "z": 8
    },
    {
      "color": {
        "a": 255,
        "b": 201,
        "g": 201,
        "r": 201
      },
      "x": 9,
      "y": 5,
      "z": 9
    },
    {
      "color": {
        "a": 255,
        "b": 201,
        "g": 201,
        "r": 201
      },
      "x": 5,
      "y": 5,
      "z": 7
    },
    {
      "color": {
        "a": 255,
        "b": 201,
        "g": 201,
        "r": 201
      },
      "x": 6,
      "y": 5,
      "z": 7
    },
    {
      "color": {
        "a": 255,
        "b": 201,
        "g": 201,
        "r": 201
      },
      "x": 8,
      "y": 3,
      "z": 7
    },
    {
      "color": {
        "a": 255,
        "b": 201,
        "g": 201,
        "r": 201
      },
      "x": 7,
      "y": 5,
      "z": 7
    },
    {
      "color": {
        "a": 255,
        "b": 201,
        "g": 201,
        "r": 201
      },
      "x": 8,
      "y": 5,
      "z": 7
    },
    {
      "color": {
        "a": 255,
        "b": 201,
        "g": 201,
        "r": 201
      },
      "x": 6,
      "y": 3,
      "z": 7
    },
    {
      "color": {
        "a": 255,
        "b": 201,
        "g": 201,
        "r": 201
      },
      "x": 9,
      "y": 5,
      "z": 7
    },
    {
      "color": {
        "a": 255,
        "b": 201,
        "g": 201,
        "r": 201
      },
      "x": 10,
      "y": 5,
      "z": 7
    },
    {
      "color": {
        "a": 255,
        "b": 201,
        "g": 201,
        "r": 201
      },
      "x": 5,
      "y": 4,
      "z": 11
    },
    {
      "color": {
        "a": 255,
        "b": 201,
        "g": 201,
        "r": 201
      },
      "x": 5,
      "y": 4,
      "z": 10
    },
    {
      "color": {
        "a": 255,
        "b": 201,
        "g": 201,
        "r": 201
      },
      "x": 5,
      "y": 4,
      "z": 9
    },
    {
      "color": {
        "a": 255,
        "b": 201,
        "g": 201,
        "r": 201
      },
      "x": 5,
      "y": 4,
      "z": 8
    },
    {
      "color": {
        "a": 255,
        "b": 201,
        "g": 201,
        "r": 201
      },
      "x": 5,
      "y": 4,
      "z": 7
    },
    {
      "color": {
        "a": 255,
        "b": 201,
        "g": 201,
        "r": 201
      },
      "x": 6,
      "y": 4,
      "z": 7
    },
    {
      "color": {
        "a": 255,
        "b": 201,
        "g": 201,
        "r": 201
      },
      "x": 6,
      "y": 4,
      "z": 8
    },
    {
      "color": {
        "a": 255,
        "b": 201,
        "g": 201,
        "r": 201
      },
      "x": 6,
      "y": 4,
      "z": 9
    },
    {
      "color": {
        "a": 255,
        "b": 201,
        "g": 201,
        "r": 201
      },
      "x": 6,
      "y": 4,
      "z": 10
    },
    {
      "color": {
        "a": 255,
        "b": 201,
        "g": 201,
        "r": 201
      },
      "x": 6,
      "y": 4,
      "z": 11
    },
    {
      "color": {
        "a": 255,
        "b": 201,
        "g": 201,
        "r": 201
      },
      "x": 7,
      "y": 4,
      "z": 11
    },
    {
      "color": {
        "a": 255,
        "b": 201,
        "g": 201,
        "r": 201
      },
      "x": 8,
      "y": 4,
      "z": 11
    },
    {
      "color": {
        "a": 255,
        "b": 201,
        "g": 201,
        "r": 201
      },
      "x": 9,
      "y": 4,
      "z": 11
    },
    {
      "color": {
        "a": 255,
        "b": 201,
        "g": 201,
        "r": 201
      },
      "x": 9,
      "y": 4,
      "z": 10
    },
    {
      "color": {
        "a": 255,
        "b": 201,
        "g": 201,
        "r": 201
      },
      "x": 10,
      "y": 4,
      "z": 11
    },
    {
      "color": {
        "a": 255,
        "b": 201,
        "g": 201,
        "r": 201
      },
      "x": 10,
      "y": 4,
      "z": 10
    },
    {
      "color": {
        "a": 255,
        "b": 201,
        "g": 201,
        "r": 201
      },
      "x": 8,
      "y": 4,
      "z": 10
    },
    {
      "color": {
        "a": 255,
        "b": 201,
        "g": 201,
        "r": 201
      },
      "x": 8,
      "y": 4,
      "z": 9
    },
    {
      "color": {
        "a": 255,
        "b": 201,
        "g": 201,
        "r": 201
      },
      "x": 9,
      "y": 4,
      "z": 9
    },
    {
      "color": {
        "a": 255,
        "b": 201,
        "g": 201,
        "r": 201
      },
      "x": 7,
      "y": 4,
      "z": 10
    },
    {
      "color": {
        "a": 255,
        "b": 201,
        "g": 201,
        "r": 201
      },
      "x": 7,
      "y": 4,
      "z": 9
    },
    {
      "color": {
        "a": 255,
        "b": 201,
        "g": 201,
        "r": 201
      },
      "x": 7,
      "y": 4,
      "z": 8
    },
    {
      "color": {
        "a": 255,
        "b": 201,
        "g": 201,
        "r": 201
      },
      "x": 8,
      "y": 4,
      "z": 8
    },
    {
      "color": {
        "a": 255,
        "b": 201,
        "g": 201,
        "r": 201
      },
      "x": 7,
      "y": 4,
      "z": 7
    },
    {
      "color": {
        "a": 255,
        "b": 201,
        "g": 201,
        "r": 201
      },
      "x": 8,
      "y": 4,
      "z": 7
    },
    {
      "color": {
        "a": 255,
        "b": 201,
        "g": 201,
        "r": 201
      },
      "x": 9,
      "y": 4,
      "z": 8
    },
    {
      "color": {
        "a": 255,
        "b": 201,
        "g": 201,
        "r": 201
      },
      "x": 10,
      "y": 4,
      "z": 9
    },
    {
      "color": {
        "a": 255,
        "b": 201,
        "g": 201,
        "r": 201
      },
      "x": 10,
      "y": 4,
      "z": 8
    },
    {
      "color": {
        "a": 255,
        "b": 201,
        "g": 201,
        "r": 201
      },
      "x": 10,
      "y": 4,
      "z": 7
    },
    {
      "color": {
        "a": 255,
        "b": 201,
        "g": 201,
        "r": 201
      },
      "x": 9,
      "y": 4,
      "z": 7
    },
    {
      "color": {
        "a": 255,
        "b": 201,
        "g": 201,
        "r": 201
      },
      "x": 5,
      "y": 3,
      "z": 11
    },
    {
      "color": {
        "a": 255,
        "b": 201,
        "g": 201,
        "r": 201
      },
      "x": 7,
      "y": 3,
      "z": 11
    },
    {
      "color": {
        "a": 255,
        "b": 201,
        "g": 201,
        "r": 201
      },
      "x": 9,
      "y": 3,
      "z": 11
    },
    {
      "color": {
        "a": 255,
        "b": 201,
        "g": 201,
        "r": 201
      },
      "x": 10,
      "y": 3,
      "z": 11
    },
    {
      "color": {
        "a": 255,
        "b": 201,
        "g": 201,
        "r": 201
      },
      "x": 10,
      "y": 3,
      "z": 10
    },
    {
      "color": {
        "a": 255,
        "b": 201,
        "g": 201,
        "r": 201
      },
      "x": 10,
      "y": 3,
      "z": 9
    },
    {
      "color": {
        "a": 255,
        "b": 201,
        "g": 201,
        "r": 201
      },
      "x": 10,
      "y": 8,
      "z": 6
    },
    {
      "color": {
        "a": 255,
        "b": 201,
        "g": 201,
        "r": 201
      },
      "x": 9,
      "y": 3,
      "z": 9
    },
    {
      "color": {
        "a": 255,
        "b": 201,
        "g": 201,
        "r": 201
      },
      "x": 9,
      "y": 8,
      "z": 6
    },
    {
      "color": {
        "a": 255,
        "b": 201,
        "g": 201,
        "r": 201
      },
      "x": 9,
      "y": 3,
      "z": 10
    },
    {
      "color": {
        "a": 255,
        "b": 201,
        "g": 201,
        "r": 201
      },
      "x": 7,
      "y": 3,
      "z": 10
    },
    {
      "color": {
        "a": 255,
        "b": 201,
        "g": 201,
        "r": 201
      },
      "x": 7,
      "y": 3,
      "z": 9
    },
    {
      "color": {
        "a": 255,
        "b": 201,
        "g": 201,
        "r": 201
      },
      "x": 7,
      "y": 8,
      "z": 6
    },
    {
      "color": {
        "a": 255,
        "b": 201,
        "g": 201,
        "r": 201
      },
      "x": 5,
      "y": 3,
      "z": 10
    },
    {
      "color": {
        "a": 255,
        "b": 201,
        "g": 201,
        "r": 201
      },
      "x": 5,
      "y": 3,
      "z": 9
    },
    {
      "color": {
        "a": 255,
        "b": 201,
        "g": 201,
        "r": 201
      },
      "x": 5,
      "y": 8,
      "z": 6
    },
    {
      "color": {
        "a": 255,
        "b": 201,
        "g": 201,
        "r": 201
      },
      "x": 5,
      "y": 3,
      "z": 8
    },
    {
      "color": {
        "a": 255,
        "b": 201,
        "g": 201,
        "r": 201
      },
      "x": 7,
      "y": 3,
      "z": 8
    },
    {
      "color": {
        "a": 255,
        "b": 201,
        "g": 201,
        "r": 201
      },
      "x": 5,
      "y": 3,
      "z": 7
    },
    {
      "color": {
        "a": 255,
        "b": 201,
        "g": 201,
        "r": 201
      },
      "x": 9,
      "y": 3,
      "z": 8
    },
    {
      "color": {
        "a": 255,
        "b": 201,
        "g": 201,
        "r": 201
      },
      "x": 10,
      "y": 3,
      "z": 8
    },
    {
      "color": {
        "a": 255,
        "b": 201,
        "g": 201,
        "r": 201
      },
      "x": 10,
      "y": 3,
      "z": 7
    },
    {
      "color": {
        "a": 255,
        "b": 201,
        "g": 201,
        "r": 201
      },
      "x": 9,
      "y": 3,
      "z": 7
    },
    {
      "color": {
        "a": 255,
        "b": 201,
        "g": 201,
        "r": 201
      },
      "x": 7,
      "y": 3,
      "z": 7
    },
    {
      "color": {
        "a": 255,
        "b": 201,
        "g": 201,
        "r": 201
      },
      "x": 5,
      "y": 4,
      "z": 6
    },
    {
      "color": {
        "a": 255,
        "b": 201,
        "g": 201,
        "r": 201
      },
      "x": 6,
      "y": 4,
      "z": 6
    },
    {
      "color": {
        "a": 255,
        "b": 201,
        "g": 201,
        "r": 201
      },
      "x": 7,
      "y": 4,
      "z": 6
    },
    {
      "color": {
        "a": 255,
        "b": 201,
        "g": 201,
        "r": 201
      },
      "x": 8,
      "y": 4,
      "z": 6
    },
    {
      "color": {
        "a": 255,
        "b": 201,
        "g": 201,
        "r": 201
      },
      "x": 9,
      "y": 4,
      "z": 6
    },
    {
      "color": {
        "a": 255,
        "b": 201,
        "g": 201,
        "r": 201
      },
      "x": 10,
      "y": 4,
      "z": 6
    },
    {
      "color": {
        "a": 255,
        "b": 201,
        "g": 201,
        "r": 201
      },
      "x": 10,
      "y": 5,
      "z": 6
    },
    {
      "color": {
        "a": 255,
        "b": 201,
        "g": 201,
        "r": 201
      },
      "x": 9,
      "y": 5,
      "z": 6
    },
    {
      "color": {
        "a": 255,
        "b": 201,
        "g": 201,
        "r": 201
      },
      "x": 7,
      "y": 5,
      "z": 6
    },
    {
      "color": {
        "a": 255,
        "b": 201,
        "g": 201,
        "r": 201
      },
      "x": 10,
      "y": 6,
      "z": 6
    },
    {
      "color": {
        "a": 255,
        "b": 201,
        "g": 201,
        "r": 201
      },
      "x": 10,
      "y": 7,
      "z": 6
    },
    {
      "color": {
        "a": 255,
        "b": 201,
        "g": 201,
        "r": 201
      },
      "x": 9,
      "y": 7,
      "z": 6
    },
    {
      "color": {
        "a": 255,
        "b": 201,
        "g": 201,
        "r": 201
      },
      "x": 7,
      "y": 6,
      "z": 6
    },
    {
      "color": {
        "a": 255,
        "b": 201,
        "g": 201,
        "r": 201
      },
      "x": 7,
      "y": 7,
      "z": 6
    },
    {
      "color": {
        "a": 255,
        "b": 201,
        "g": 201,
        "r": 201
      },
      "x": 5,
      "y": 7,
      "z": 6
    },
    {
      "color": {
        "a": 255,
        "b": 201,
        "g": 201,
        "r": 201
      },
      "x": 5,
      "y": 6,
      "z": 6
    },
    {
      "color": {
        "a": 255,
        "b": 201,
        "g": 201,
        "r": 201
      },
      "x": 5,
      "y": 5,
      "z": 6
    }
  ]
}
