{
  "assetId": "torso_1",
  "attachments": [
    {
      "forward": {
        "x": 1.0,
        "y": 0.0,
        "z": 0.0
      },
      "name": "head",
      "position": {
        "x": 0.5,
        "y": 0.5625,
        "z": 0.5625
      },
      "up": {
        "x": -0.0,
        "y": 1.0,
        "z": 0.0
      }
    },
    {
      "forward": {
        "x": 1.0,
        "y": 0.0,
        "z": 0.0
      },
      "name": "left_hand",
      "position": {
        "x": 0.1875,
        "y": 0.5,
        "z": 0.6875
      },
      "up": {
        "x": -0.0,
        "y": 1.0,
        "z": 0.0
      }
    },
    {
      "forward": {
        "x": 1.0,
        "y": 0.0,
        "z": 0.0
      },
      "name": "right_hand",
      "position": {
        "x": 0.8125,
        "y": 0.5,
        "z": 0.6875
      },
      "up": {
        "x": -0.0,
        "y": 1.0,
        "z": 0.0
      }
    },
    {
      "forward": {
        "x": -1.0,
        "y": 0.0,
        "z": 0.0
      },
      "name": "shoe_left",
      "position": {
        "x": 0.375,
        "y": 0.0,
        "z": 0.5625
      },
      "up": {
        "x": 0.0,
        "y": 1.0,
        "z": -0.0
      }
    },
    {
      "forward": {
        "x": 1.0,
        "y": 0.0,
        "z": 0.0
      },
      "name": "shoe_right",
      "position": {
        "x": 0.625,
        "y": 0.0,
        "z": 0.5625
      },
      "up": {
        "x": -0.0,
        "y": 1.0,
        "z": 0.0
      }
    }
  ],
  "displayName": "torso_1",
  "pivot": {
    "x": 0.5,
    "y": 0.375,
    "z": 0.5625
  },
  "version": 2,
  "voxelSize": 0.0625,
  "voxels": [
    {
      "color": {
        "a": 255,
        "b": 201,
        "g": 201,
        "r": 201
      },
      "x": 5,
      "y": 8,
      "z": 7
    },
    {
      "color": {
        "a": 255,
        "b": 201,
        "g": 201,
        "r": 201
      },
      "x": 8,
      "y": 8,
      "z": 8
    },
    {
      "color": {
        "a": 255,
        "b": 201,
        "g": 201,
        "r": 201
      },
      "x": 6,
      "y": 8,
      "z": 11
    },
    {
      "color": {
        "a": 255,
        "b": 201,
        "g": 201,
        "r": 201
      },
      "x": 7,
      "y": 8,
      "z": 8
    },
    {
      "color": {
        "a": 255,
        "b": 134,
        "g": 134,
        "r": 134
      },
      "x": 6,
      "y": 5,
      "z": 6
    },
    {
      "color": {
        "a": 255,
        "b": 201,
        "g": 201,
        "r": 201
      },
      "x": 8,
      "y": 8,
      "z": 9
    },
    {
      "color": {
        "a": 255,
        "b": 201,
        "g": 201,
        "r": 201
      },
      "x": 8,
      "y": 3,
      "z": 6
    },
    {
      "color": {
        "a": 255,
        "b": 201,
        "g": 201,
        "r": 201
      },
      "x": 7,
      "y": 8,
      "z": 9
    },
    {
      "color": {
        "a": 255,
        "b": 201,
        "g": 201,
        "r": 201
      },
      "x": 7,
      "y": 3,
      "z": 6
    },
    {
      "color": {
        "a": 255,
        "b": 201,
        "g": 201,
        "r": 201
      },
      "x": 5,
      "y": 7,
      "z": 10
    },
    {
      "color": {
        "a": 255,
        "b": 201,
        "g": 201,
        "r": 201
      },
      "x": 7,
      "y": 8,
      "z": 11
    },
    {
      "color": {
        "a": 255,
        "b": 201,
        "g": 201,
        "r": 201
      },
      "x": 6,
      "y": 8,
      "z": 8
    },
    {
      "color": {
        "a": 255,
        "b": 201,
        "g": 201,
        "r": 201
      },
      "x": 6,
      "y": 8,
      "z": 9
    },
    {
      "color": {
        "a": 255,
        "b": 201,
        "g": 201,
        "r": 201
      },
      "x": 6,
      "y": 3,
      "z": 6
    },
    {
      "color": {
        "a": 255,
        "b": 134,
        "g": 134,
        "r": 134
      },
      "x": 8,
      "y": 5,
      "z": 6
    },
    {
      "color": {
        "a": 255,
        "b": 201,
        "g": 201,
        "r": 201
      },
      "x": 6,
      "y": 7,
      "z": 10
    },
    {
      "color": {
        "a": 255,
        "b": 201,
        "g": 201,
        "r": 201
      },
      "x": 8,
      "y": 8,
      "z": 7
    },
    {
      "color": {
        "a": 255,
        "b": 201,
        "g": 201,
        "r": 201
      },
      "x": 5,
      "y": 8,
      "z": 8
    },
    {
      "color": {
        "a": 255,
        "b": 201,
        "g": 201,
        "r": 201
      },
      "x": 5,
      "y": 8,
      "z": 9
    },
    {
      "color": {
        "a": 255,
        "b": 201,
        "g": 201,
        "r": 201
      },
      "x": 5,
      "y": 3,
      "z": 6
    },
    {
      "color": {
        "a": 255,
        "b": 201,
        "g": 201,
        "r": 201
      },
      "x": 7,
      "y": 7,
      "z": 10
    },
    {
      "color": {
        "a": 255,
        "b": 83,
        "g": 83,
        "r": 83
      },
      "x": 5,
      "y": 8,
      "z": 11
    },
    {
      "color": {
        "a": 255,
        "b": 201,
        "g": 201,
        "r": 201
      },
      "x": 8,
      "y": 7,
      "z": 10
    },
    {
      "color": {
        "a": 255,
        "b": 201,
        "g": 201,
        "r": 201
      },
      "x": 6,
      "y": 8,
      "z": 7
    },
    {
      "color": {
        "a": 255,
        "b": 201,
        "g": 201,
        "r": 201
      },
      "x": 9,
      "y": 8,
      "z": 9
    },
    {
      "color": {
        "a": 255,
        "b": 201,
        "g": 201,
        "r": 201
      },
      "x": 9,
      "y": 3,
      "z": 6
    },
    {
      "color": {
        "a": 255,
        "b": 201,
        "g": 201,
        "r": 201
      },
      "x": 9,
      "y": 8,
      "z": 8
    },
    {
      "color": {
        "a": 255,
        "b": 201,
        "g": 201,
        "r": 201
      },
      "x": 10,
      "y": 8,
      "z": 9
    },
    {
      "color": {
        "a": 255,
        "b": 201,
        "g": 201,
        "r": 201
      },
      "x": 10,
      "y": 3,
      "z": 6
    },
    {
      "color": {
        "a": 255,
        "b": 201,
        "g": 201,
        "r": 201
      },
      "x": 10,
      "y": 8,
      "z": 8
    },
    {
      "color": {
        "a": 255,
        "b": 201,
        "g": 201,
        "r": 201
      },
      "x": 8,
      "y": 7,
      "z": 7
    },
    {
      "color": {
        "a": 255,
        "b": 201,
        "g": 201,
        "r": 201
      },
      "x": 6,
      "y": 1,
      "z": 7
    },
    {
      "color": {
        "a": 255,
        "b": 201,
        "g": 201,
        "r": 201
      },
      "x": 5,
      "y": 7,
      "z": 8
    },
    {
      "color": {
        "a": 255,
        "b": 201,
        "g": 201,
        "r": 201
      },
      "x": 6,
      "y": 8,
      "z": 10
    },
    {
      "color": {
        "a": 255,
        "b": 201,
        "g": 201,
        "r": 201
      },
      "x": 5,
      "y": 7,
      "z": 11
    },
    {
      "color": {
        "a": 255,
        "b": 201,
        "g": 201,
        "r": 201
      },
      "x": 7,
      "y": 8,
      "z": 10
    },
    {
      "color": {
        "a": 255,
        "b": 201,
        "g": 201,
        "r": 201
      },
      "x": 6,
      "y": 7,
      "z": 8
    },
    {
      "color": {
        "a": 255,
        "b": 201,
        "g": 201,
        "r": 201
      },
      "x": 8,
      "y": 1,
      "z": 8
    },
    {
      "color": {
        "a": 255,
        "b": 201,
        "g": 201,
        "r": 201
      },
      "x": 7,
      "y": 7,
      "z": 11
    },
    {
      "color": {
        "a": 255,
        "b": 201,
        "g": 201,
        "r": 201
      },
      "x": 5,
      "y": 8,
      "z": 10
    },
    {
      "color": {
        "a": 255,
        "b": 201,
        "g": 201,
        "r": 201
      },
      "x": 6,
      "y": 7,
      "z": 7
    },
    {
      "color": {
        "a": 255,
        "b": 201,
        "g": 201,
        "r": 201
      },
      "x": 8,
      "y": 1,
      "z": 7
    },
    {
      "color": {
        "a": 255,
        "b": 201,
        "g": 201,
        "r": 201
      },
      "x": 8,
      "y": 8,
      "z": 10
    },
    {
      "color": {
        "a": 255,
        "b": 201,
        "g": 201,
        "r": 201
      },
      "x": 10,
      "y": 8,
      "z": 7
    },
    {
      "color": {
        "a": 255,
        "b": 201,
        "g": 201,
        "r": 201
      },
      "x": 9,
      "y": 8,
      "z": 10
    },
    {
      "color": {
        "a": 255,
        "b": 201,
        "g": 201,
        "r": 201
      },
      "x": 9,
      "y": 8,
      "z": 7
    },
    {
      "color": {
        "a": 255,
        "b": 201,
        "g": 201,
        "r": 201
      },
      "x": 10,
      "y": 8,
      "z": 10
    },
    {
      "color": {
        "a": 255,
        "b": 201,
        "g": 201,
        "r": 201
      },
      "x": 7,
      "y": 8,
      "z": 7
    },
    {
      "color": {
        "a": 255,
        "b": 201,
        "g": 201,
        "r": 201
      },
      "x": 8,
      "y": 8,
      "z": 11
    },
    {
      "color": {
        "a": 255,
        "b": 201,
        "g": 201,
        "r": 201
      },
      "x": 7,
      "y": 7,
      "z": 8
    },
    {
      "color": {
        "a": 255,
        "b": 201,
        "g": 201,
        "r": 201
      },
      "x": 8,
      "y": 1,
      "z": 11
    },
    {
      "color": {
        "a": 255,
        "b": 83,
        "g": 83,
        "r": 83
      },
      "x": 6,
      "y": 7,
      "z": 11
    },
    {
      "color": {
        "a": 255,
        "b": 201,
        "g": 201,
        "r": 201
      },
      "x": 6,
      "y": 1,
      "z": 11
    },
    {
      "color": {
        "a": 255,
        "b": 201,
        "g": 201,
        "r": 201
      },
      "x": 8,
      "y": 7,
      "z": 11
    },
    {
      "color": {
        "a": 255,
        "b": 201,
        "g": 201,
        "r": 201
      },
      "x": 5,
      "y": 7,
      "z": 7
    },
    {
      "color": {
        "a": 255,
        "b": 201,
        "g": 201,
        "r": 201
      },
      "x": 8,
      "y": 7,
      "z": 8
    },
    {
      "color": {
        "a": 255,
        "b": 201,
        "g": 201,
        "r": 201
      },
      "x": 6,
      "y": 1,
      "z": 8
    },
    {
      "color": {
        "a": 255,
        "b": 201,
        "g": 201,
        "r": 201
      },
      "x": 10,
      "y": 7,
      "z": 9
    },
    {
      "color": {
        "a": 255,
        "b": 201,
        "g": 201,
        "r": 201
      },
      "x": 9,
      "y": 7,
      "z": 9
    },
    {
      "color": {
        "a": 255,
        "b": 201,
        "g": 201,
        "r": 201
      },
      "x": 10,
      "y": 7,
      "z": 7
    },
    {
      "color": {
        "a": 255,
        "b": 201,
        "g": 201,
        "r": 201
      },
      "x": 9,
      "y": 7,
      "z": 10
    },
    {
      "color": {
        "a": 255,
        "b": 201,
        "g": 201,
        "r": 201
      },
      "x": 6,
      "y": 7,
      "z": 9
    },
    {
      "color": {
        "a": 255,
        "b": 201,
        "g": 201,
        "r": 201
      },
      "x": 8,
      "y": 6,
      "z": 6
    },
    {
      "color": {
        "a": 255,
        "b": 201,
        "g": 201,
        "r": 201
      },
      "x": 5,
      "y": 7,
      "z": 9
    },
    {
      "color": {
        "a": 255,
        "b": 201,
        "g": 201,
        "r": 201
      },
      "x": 7,
      "y": 7,
      "z": 9
    },
    {
      "color": {
        "a": 255,
        "b": 201,
        "g": 201,
        "r": 201
      },
      "x": 6,
      "y": 1,
      "z": 9
    },
    {
      "color": {
        "a": 255,
        "b": 201,
        "g": 201,
        "r": 201
      },
      "x": 6,
      "y": 6,
      "z": 6
    },
    {
      "color": {
        "a": 255,
        "b": 201,
        "g": 201,
        "r": 201
      },
      "x": 8,
      "y": 7,
      "z": 9
    },
    {
      "color": {
        "a": 255,
        "b": 201,
        "g": 201,
        "r": 201
      },
      "x": 9,
      "y": 7,
      "z": 7
    },
    {
      "color": {
        "a": 255,
        "b": 201,
        "g": 201,
        "r": 201
      },
      "x": 10,
      "y": 7,
      "z": 10
    },
    {
      "color": {
        "a": 255,
        "b": 201,
        "g": 201,
        "r": 201
      },
      "x": 7,
      "y": 7,
      "z": 7
    },
    {
      "color": {
        "a": 255,
        "b": 201,
        "g": 201,
        "r": 201
      },
      "x": 9,
      "y": 7,
      "z": 8
    },
    {
      "color": {
        "a": 255,
        "b": 201,
        "g": 201,
        "r": 201
      },
      "x": 10,
      "y": 7,
      "z": 8
    },
    {
      "color": {
        "a": 255,
        "b": 201,
        "g": 201,
        "r": 201
      },
      "x": 5,
      "y": 6,
      "z": 11
    },
    {
      "color": {
        "a": 255,
        "b": 201,
        "g": 201,
        "r": 201
      },
      "x": 7,
      "y": 5,
      "z": 10
    },
    {
      "color": {
        "a": 255,
        "b": 65,
        "g": 65,
        "r": 65
      },
      "x": 7,
      "y": 5,
      "z": 11
    },
    {
      "color": {
        "a": 255,
        "b": 201,
        "g": 201,
        "r": 201
      },
      "x": 5,
      "y": 6,
      "z": 10
    },
    {
      "color": {
        "a": 255,
        "b": 201,
        "g": 201,
        "r": 201
      },
      "x": 5,
      "y": 1,
      "z": 6
    },
    {
      "color": {
        "a": 255,
        "b": 201,
        "g": 201,
        "r": 201
      },
      "x": 5,
      "y": 6,
      "z": 9
    },
    {
      "color": {
        "a": 255,
        "b": 201,
        "g": 201,
        "r": 201
      },
      "x": 5,
      "y": 6,
      "z": 8
    },
    {
      "color": {
        "a": 255,
        "b": 201,
        "g": 201,
        "r": 201
      },
      "x": 5,
      "y": 6,
      "z": 7
    },
    {
      "color": {
        "a": 255,
        "b": 201,
        "g": 201,
        "r": 201
      },
      "x": 6,
      "y": 6,
      "z": 7
    },
    {
      "color": {
        "a": 255,
        "b": 201,
        "g": 201,
        "r": 201
      },
      "x": 6,
      "y": 6,
      "z": 8
    },
    {
      "color": {
        "a": 255,
        "b": 201,
        "g": 201,
        "r": 201
      },
      "x": 6,
      "y": 1,
      "z": 6
    },
    {
      "color": {
        "a": 255,
        "b": 201,
        "g": 201,
        "r": 201
      },
      "x": 6,
      "y": 6,
      "z": 9
    },
    {
      "color": {
        "a": 255,
        "b": 201,
        "g": 201,
        "r": 201
      },
      "x": 8,
      "y": 7,
      "z": 6
    },
    {
      "color": {
        "a": 255,
        "b": 201,
        "g": 201,
        "r": 201
      },
      "x": 6,
      "y": 6,
      "z": 10
    },
    {
      "color": {
        "a": 255,
        "b": 201,
        "g": 201,
        "r": 201
      },
      "x": 6,
      "y": 6,
      "z": 11
    },
    {
      "color": {
        "a": 255,
        "b": 134,
        "g": 134,
        "r": 134
      },
      "x": 5,
      "y": 5,
      "z": 11
    },
    {
      "color": {
        "a": 255,
        "b": 201,
        "g": 201,
        "r": 201
      },
      "x": 7,
      "y": 6,
      "z": 10
    },
    {
      "color": {
        "a": 255,
        "b": 201,
        "g": 201,
        "r": 201
      },
      "x": 7,
      "y": 1,
      "z": 6
    },
    {
      "color": {
        "a": 255,
        "b": 201,
        "g": 201,
        "r": 201
      },
      "x": 7,
      "y": 6,
      "z": 9
    },
    {
      "color": {
        "a": 255,
        "b": 201,
        "g": 201,
        "r": 201
      },
      "x": 7,
      "y": 6,
      "z": 8
    },
    {
      "color": {
        "a": 255,
        "b": 201,
        "g": 201,
        "r": 201
      },
      "x": 8,
      "y": 6,
      "z": 8
    },
    {
      "color": {
        "a": 255,
        "b": 201,
        "g": 201,
        "r": 201
      },
      "x": 8,
      "y": 1,
      "z": 6
    },
    {
      "color": {
        "a": 255,
        "b": 201,
        "g": 201,
        "r": 201
      },
      "x": 8,
      "y": 6,
      "z": 9
    },
    {
      "color": {
        "a": 255,
        "b": 201,
        "g": 201,
        "r": 201
      },
      "x": 6,
      "y": 7,
      "z": 6
    },
    {
      "color": {
        "a": 255,
        "b": 201,
        "g": 201,
        "r": 201
      },
      "x": 8,
      "y": 6,
      "z": 10
    },
    {
      "color": {
        "a": 255,
        "b": 201,
        "g": 201,
        "r": 201
      },
      "x": 9,
      "y": 6,
      "z": 10
    },
    {
      "color": {
        "a": 255,
        "b": 201,
        "g": 201,
        "r": 201
      },
      "x": 9,
      "y": 1,
      "z": 6
    },
    {
      "color": {
        "a": 255,
        "b": 201,
        "g": 201,
        "r": 201
      },
      "x": 9,
      "y": 6,
      "z": 9
    },
    {
      "color": {
        "a": 255,
        "b": 201,
        "g": 201,
        "r": 201
      },
      "x": 9,
      "y": 6,
      "z": 8
    },
    {
      "color": {
        "a": 255,
        "b": 201,
        "g": 201,
        "r": 201
      },
      "x": 10,
      "y": 1,
      "z": 6
    },
    {
      "color": {
        "a": 255,
        "b": 201,
        "g": 201,
        "r": 201
      },
      "x": 10,
      "y": 6,
      "z": 9
    },
    {
      "color": {
        "a": 255,
        "b": 201,
        "g": 201,
        "r": 201
      },
      "x": 10,
      "y": 6,
      "z": 10
    },
    {
      "color": {
        "a": 255,
        "b": 201,
        "g": 201,
        "r": 201
      },
      "x": 10,
      "y": 6,
      "z": 11
    },
    {
      "color": {
        "a": 255,
        "b": 201,
        "g": 201,
        "r": 201
      },
      "x": 10,
      "y": 6,
      "z": 8
    },
    {
      "color": {
        "a": 255,
        "b": 201,
        "g": 201,
        "r": 201
      },
      "x": 10,
      "y": 6,
      "z": 7
    },
    {
      "color": {
        "a": 255,
        "b": 201,
        "g": 201,
        "r": 201
      },
      "x": 9,
      "y": 6,
      "z": 7
    },
    {
      "color": {
        "a": 255,
        "b": 201,
        "g": 201,
        "r": 201
      },
      "x": 8,
      "y": 6,
      "z": 7
    },
    {
      "color": {
        "a": 255,
        "b": 201,
        "g": 201,
        "r": 201
      },
      "x": 7,
      "y": 6,
      "z": 7
    },
    {
      "color": {
        "a": 255,
        "b": 201,
        "g": 201,
        "r": 201
      },
      "x": 6,
      "y": 5,
      "z": 9
    },
    {
      "color": {
        "a": 255,
        "b": 201,
        "g": 201,
        "r": 201
      },
      "x": 8,
      "y": 3,
      "z": 9
    },
    {
      "color": {
        "a": 255,
        "b": 201,
        "g": 201,
        "r": 201
      },
      "x": 8,
      "y": 8,
      "z": 6
    },
    {
      "color": {
        "a": 255,
        "b": 134,
        "g": 134,
        "r": 134
      },
      "x": 6,
      "y": 5,
      "z": 10
    },
    {
      "color": {
        "a": 255,
        "b": 201,
        "g": 201,
        "r": 201
      },
      "x": 8,
      "y": 3,
      "z": 10
    },
    {
      "color": {
        "a": 255,
        "b": 135,
        "g": 135,
        "r": 135
      },
      "x": 8,
      "y": 3,
      "z": 11
    },
    {
      "color": {
        "a": 255,
        "b": 134,
        "g": 134,
        "r": 134
      },
      "x": 6,
      "y": 5,
      "z": 11
    },
    {
      "color": {
        "a": 255,
        "b": 153,
        "g": 153,
        "r": 153
      },
      "x": 6,
      "y": 3,
      "z": 11
    },
    {
      "color": {
        "a": 255,
        "b": 65,
        "g": 65,
        "r": 65
      },
      "x": 8,
      "y": 5,
      "z": 11
    },
    {
      "color": {
        "a": 255,
        "b": 201,
        "g": 201,
        "r": 201
      },
      "x": 8,
      "y": 5,
      "z": 10
    },
    {
      "color": {
        "a": 255,
        "b": 201,
        "g": 201,
        "r": 201
      },
      "x": 6,
      "y": 3,
      "z": 10
    },
    {
      "color": {
        "a": 255,
        "b": 201,
        "g": 201,
        "r": 201
      },
      "x": 8,
      "y": 5,
      "z": 9
    },
    {
      "color": {
        "a": 255,
        "b": 201,
        "g": 201,
        "r": 201
      },
      "x": 6,
      "y": 3,
      "z": 9
    },
    {
      "color": {
        "a": 255,
        "b": 201,
        "g": 201,
        "r": 201
      },
      "x": 6,
      "y": 8,
      "z": 6
    },
    {
      "color": {
        "a": 255,
        "b": 201,
        "g": 201,
        "r": 201
      },
      "x": 7,
      "y": 5,
      "z": 9
    },
    {
      "color": {
        "a": 255,
        "b": 201,
        "g": 201,
        "r": 201
      },
      "x": 9,
      "y": 5,
      "z": 10
    },
    {
      "color": {
        "a": 255,
        "b": 201,
        "g": 201,
        "r": 201
      },
      "x": 9,
      "y": 5,
      "z": 8
    },
    {
      "color": {
        "a": 255,
        "b": 201,
        "g": 201,
        "r": 201
      },
      "x": 8,
      "y": 5,
      "z": 8
    },
    {
      "color": {
        "a": 255,
        "b": 201,
        "g": 201,
        "r": 201
      },
      "x": 6,
      "y": 3,
      "z": 8
    },
    {
      "color": {
        "a": 255,
        "b": 201,
        "g": 201,
        "r": 201
      },
      "x": 7,
      "y": 5,
      "z": 8
    },
    {
      "color": {
        "a": 255,
        "b": 201,
        "g": 201,
        "r": 201
      },
      "x": 6,
      "y": 5,
      "z": 8
    },
    {
      "color": {
        "a": 255,
        "b": 201,
        "g": 201,
        "r": 201
      },
      "x": 8,
      "y": 3,
      "z": 8
    },
    {
      "color": {
        "a": 255,
        "b": 201,
        "g": 201,
        "r": 201
      },
      "x": 9,
      "y": 5,
      "z": 9
    },
    {
      "color": {
        "a": 255,
        "b": 201,
        "g": 201,
        "r": 201
      },
      "x": 6,
      "y": 5,
      "z": 7
    },
    {
      "color": {
        "a": 255,
        "b": 201,
        "g": 201,
        "r": 201
      },
      "x": 8,
      "y": 3,
      "z": 7
    },
    {
      "color": {
        "a": 255,
        "b": 201,
        "g": 201,
        "r": 201
      },
      "x": 7,
      "y": 5,
      "z": 7
    },
    {
      "color": {
        "a": 255,
        "b": 201,
        "g": 201,
        "r": 201
      },
      "x": 8,
      "y": 5,
      "z": 7
    },
    {
      "color": {
        "a": 255,
        "b": 201,
        "g": 201,
        "r": 201
      },
      "x": 6,
      "y": 3,
      "z": 7
    },
    {
      "color": {
        "a": 255,
        "b": 201,
        "g": 201,
        "r": 201
      },
      "x": 9,
      "y": 5,
      "z": 7
    },
    {
      "color": {
        "a": 255,
        "b": 134,
        "g": 134,
        "r": 134
      },
      "x": 5,
      "y": 4,
      "z": 8
    },
    {
      "color": {
        "a": 255,
        "b": 201,
        "g": 201,
        "r": 201
      },
      "x": 7,
      "y": 1,
      "z": 7
    },
    {
      "color": {
        "a": 255,
        "b": 134,
        "g": 134,
        "r": 134
      },
      "x": 5,
      "y": 4,
      "z": 7
    },
    {
      "color": {
        "a": 255,
        "b": 201,
        "g": 201,
        "r": 201
      },
      "x": 7,
      "y": 1,
      "z": 8
    },
    {
      "color": {
        "a": 255,
        "b": 201,
        "g": 201,
        "r": 201
      },
      "x": 6,
      "y": 4,
      "z": 7
    },
    {
      "color": {
        "a": 255,
        "b": 201,
        "g": 201,
        "r": 201
      },
      "x": 6,
      "y": 4,
      "z": 8
    },
    {
      "color": {
        "a": 255,
        "b": 201,
        "g": 201,
        "r": 201
      },
      "x": 6,
      "y": 4,
      "z": 9
    },
    {
      "color": {
        "a": 255,
        "b": 201,
        "g": 201,
        "r": 201
      },
      "x": 9,
      "y": 4,
      "z": 10
    },
    {
      "color": {
        "a": 255,
        "b": 201,
        "g": 201,
        "r": 201
      },
      "x": 8,
      "y": 4,
      "z": 10
    },
    {
      "color": {
        "a": 255,
        "b": 201,
        "g": 201,
        "r": 201
      },
      "x": 8,
      "y": 4,
      "z": 9
    },
    {
      "color": {
        "a": 255,
        "b": 201,
        "g": 201,
        "r": 201
      },
      "x": 9,
      "y": 4,
      "z": 9
    },
    {
      "color": {
        "a": 255,
        "b": 201,
        "g": 201,
        "r": 201
      },
      "x": 7,
      "y": 4,
      "z": 10
    },
    {
      "color": {
        "a": 255,
        "b": 201,
        "g": 201,
        "r": 201
      },
      "x": 7,
      "y": 4,
      "z": 9
    },
    {
      "color": {
        "a": 255,
        "b": 201,
        "g": 201,
        "r": 201
      },
      "x": 5,
      "y": 1,
      "z": 7
    },
    {
      "color": {
        "a": 255,
        "b": 201,
        "g": 201,
        "r": 201
      },
      "x": 7,
      "y": 4,
      "z": 8
    },
    {
      "color": {
        "a": 255,
        "b": 201,
        "g": 201,
        "r": 201
      },
      "x": 8,
      "y": 4,
      "z": 8
    },
    {
      "color": {
        "a": 255,
        "b": 201,
        "g": 201,
        "r": 201
      },
      "x": 5,
      "y": 1,
      "z": 8
    },
    {
      "color": {
        "a": 255,
        "b": 201,
        "g": 201,
        "r": 201
      },
      "x": 7,
      "y": 4,
      "z": 7
    },
    {
      "color": {
        "a": 255,
        "b": 201,
        "g": 201,
        "r": 201
      },
      "x": 8,
      "y": 4,
      "z": 7
    },
    {
      "color": {
        "a": 255,
        "b": 201,
        "g": 201,
        "r": 201
      },
      "x": 9,
      "y": 4,
      "z": 8
    },
    {
      "color": {
        "a": 255,
        "b": 201,
        "g": 201,
        "r": 201
      },
      "x": 9,
      "y": 4,
      "z": 7
    },
    {
      "color": {
        "a": 255,
        "b": 201,
        "g": 201,
        "r": 201
      },
      "x": 10,
      "y": 3,
      "z": 10
    },
    {
      "color": {
        "a": 255,
        "b": 201,
        "g": 201,
        "r": 201
      },
      "x": 10,
      "y": 3,
      "z": 9
    },
    {
      "color": {
        "a": 255,
        "b": 201,
        "g": 201,
        "r": 201
      },
      "x": 10,
      "y": 8,
      "z": 6
    },
    {
      "color": {
        "a": 255,
        "b": 201,
        "g": 201,
        "r": 201
      },
      "x": 9,
      "y": 3,
      "z": 9
    },
    {
      "color": {
        "a": 255,
        "b": 201,
        "g": 201,
        "r": 201
      },
      "x": 9,
      "y": 8,
      "z": 6
    },
    {
      "color": {
        "a": 255,
        "b": 201,
        "g": 201,
        "r": 201
      },
      "x": 9,
      "y": 3,
      "z": 10
    },
    {
      "color": {
        "a": 255,
        "b": 201,
        "g": 201,
        "r": 201
      },
      "x": 7,
      "y": 3,
      "z": 10
    },
    {
      "color": {
        "a": 255,
        "b": 201,
        "g": 201,
        "r": 201
      },
      "x": 7,
      "y": 3,
      "z": 9
    },
    {
      "color": {
        "a": 255,
        "b": 201,
        "g": 201,
        "r": 201
      },
      "x": 7,
      "y": 8,
      "z": 6
    },
    {
      "color": {
        "a": 255,
        "b": 201,
        "g": 201,
        "r": 201
      },
      "x": 5,
      "y": 3,
      "z": 10
    },
    {
      "color": {
        "a": 255,
        "b": 201,
        "g": 201,
        "r": 201
      },
      "x": 5,
      "y": 3,
      "z": 9
    },
    {
      "color": {
        "a": 255,
        "b": 201,
        "g": 201,
        "r": 201
      },
      "x": 5,
      "y": 8,
      "z": 6
    },
    {
      "color": {
        "a": 255,
        "b": 201,
        "g": 201,
        "r": 201
      },
      "x": 7,
      "y": 2,
      "z": 7
    },
    {
      "color": {
        "a": 255,
        "b": 201,
        "g": 201,
        "r": 201
      },
      "x": 5,
      "y": 3,
      "z": 8
    },
    {
      "color": {
        "a": 255,
        "b": 201,
        "g": 201,
        "r": 201
      },
      "x": 5,
      "y": 2,
      "z": 7
    },
    {
      "color": {
        "a": 255,
        "b": 201,
        "g": 201,
        "r": 201
      },
      "x": 7,
      "y": 3,
      "z": 8
    },
    {
      "color": {
        "a": 255,
        "b": 201,
        "g": 201,
        "r": 201
      },
      "x": 7,
      "y": 2,
      "z": 8
    },
    {
      "color": {
        "a": 255,
        "b": 201,
        "g": 201,
        "r": 201
      },
      "x": 5,
      "y": 3,
      "z": 7
    },
    {
      "color": {
        "a": 255,
        "b": 201,
        "g": 201,
        "r": 201
      },
      "x": 9,
      "y": 3,
      "z": 8
    },
    {
      "color": {
        "a": 255,
        "b": 201,
        "g": 201,
        "r": 201
      },
      "x": 10,
      "y": 3,
      "z": 8
    },
    {
      "color": {
        "a": 255,
        "b": 201,
        "g": 201,
        "r": 201
      },
      "x": 10,
      "y": 3,
      "z": 7
    },
    {
      "color": {
        "a": 255,
        "b": 201,
        "g": 201,
        "r": 201
      },
      "x": 9,
      "y": 3,
      "z": 7
    },
    {
      "color": {
        "a": 255,
        "b": 201,
        "g": 201,
        "r": 201
      },
      "x": 5,
      "y": 2,
      "z": 8
    },
    {
      "color": {
        "a": 255,
        "b": 201,
        "g": 201,
        "r": 201
      },
      "x": 7,
      "y": 3,
      "z": 7
    },
    {
      "color": {
        "a": 255,
        "b": 201,
        "g": 201,
        "r": 201
      },
      "x": 10,
      "y": 1,
      "z": 9
    },
    {
      "color": {
        "a": 255,
        "b": 201,
        "g": 201,
        "r": 201
      },
      "x": 10,
      "y": 6,
      "z": 6
    },
    {
      "color": {
        "a": 255,
        "b": 201,
        "g": 201,
        "r": 201
      },
      "x": 10,
      "y": 7,
      "z": 6
    },
    {
      "color": {
        "a": 255,
        "b": 201,
        "g": 201,
        "r": 201
      },
      "x": 9,
      "y": 7,
      "z": 6
    },
    {
      "color": {
        "a": 255,
        "b": 201,
        "g": 201,
        "r": 201
      },
      "x": 7,
      "y": 6,
      "z": 6
    },
    {
      "color": {
        "a": 255,
        "b": 201,
        "g": 201,
        "r": 201
      },
      "x": 7,
      "y": 7,
      "z": 6
    },
    {
      "color": {
        "a": 255,
        "b": 201,
        "g": 201,
        "r": 201
      },
      "x": 5,
      "y": 7,
      "z": 6
    },
    {
      "color": {
        "a": 255,
        "b": 201,
        "g": 201,
        "r": 201
      },
      "x": 5,
      "y": 1,
      "z": 9
    },
    {
      "color": {
        "a": 255,
        "b": 201,
        "g": 201,
        "r": 201
      },
      "x": 5,
      "y": 6,
      "z": 6
    },
    {
      "color": {
        "a": 255,
        "b": 201,
        "g": 201,
        "r": 201
      },
      "x": 5,
      "y": 2,
      "z": 11
    },
    {
      "color": {
        "a": 255,
        "b": 201,
        "g": 201,
        "r": 201
      },
      "x": 7,
      "y": 2,
      "z": 11
    },
    {
      "color": {
        "a": 255,
        "b": 201,
        "g": 201,
        "r": 201
      },
      "x": 8,
      "y": 2,
      "z": 11
    },
    {
      "color": {
        "a": 255,
        "b": 201,
        "g": 201,
        "r": 201
      },
      "x": 9,
      "y": 2,
      "z": 10
    },
    {
      "color": {
        "a": 255,
        "b": 201,
        "g": 201,
        "r": 201
      },
      "x": 9,
      "y": 2,
      "z": 11
    },
    {
      "color": {
        "a": 255,
        "b": 201,
        "g": 201,
        "r": 201
      },
      "x": 10,
      "y": 2,
      "z": 11
    },
    {
      "color": {
        "a": 255,
        "b": 201,
        "g": 201,
        "r": 201
      },
      "x": 10,
      "y": 2,
      "z": 10
    },
    {
      "color": {
        "a": 255,
        "b": 201,
        "g": 201,
        "r": 201
      },
      "x": 10,
      "y": 2,
      "z": 9
    },
    {
      "color": {
        "a": 255,
        "b": 201,
        "g": 201,
        "r": 201
      },
      "x": 10,
      "y": 2,
      "z": 8
    },
    {
      "color": {
        "a": 255,
        "b": 201,
        "g": 201,
        "r": 201
      },
      "x": 10,
      "y": 2,
      "z": 7
    },
    {
      "color": {
        "a": 255,
        "b": 201,
        "g": 201,
        "r": 201
      },
      "x": 10,
      "y": 2,
      "z": 6
    },
    {
      "color": {
        "a": 255,
        "b": 201,
        "g": 201,
        "r": 201
      },
      "x": 9,
      "y": 2,
      "z": 9
    },
    {
      "color": {
        "a": 255,
        "b": 201,
        "g": 201,
        "r": 201
      },
      "x": 9,
      "y": 2,
      "z": 8
    },
    {
      "color": {
        "a": 255,
        "b": 201,
        "g": 201,
        "r": 201
      },
      "x": 9,
      "y": 2,
      "z": 7
    },
    {
      "color": {
        "a": 255,
        "b": 201,
        "g": 201,
        "r": 201
      },
      "x": 9,
      "y": 2,
      "z": 6
    },
    {
      "color": {
        "a": 255,
        "b": 201,
        "g": 201,
        "r": 201
      },
      "x": 8,
      "y": 2,
      "z": 10
    },
    {
      "color": {
        "a": 255,
        "b": 201,
        "g": 201,
        "r": 201
      },
      "x": 8,
      "y": 2,
      "z": 9
    },
    {
      "color": {
        "a": 255,
        "b": 201,
        "g": 201,
        "r": 201
      },
      "x": 8,
      "y": 2,
      "z": 8
    },
    {
      "color": {
        "a": 255,
        "b": 201,
        "g": 201,
        "r": 201
      },
      "x": 8,
      "y": 2,
      "z": 7
    },
    {
      "color": {
        "a": 255,
        "b": 201,
        "g": 201,
        "r": 201
      },
      "x": 7,
      "y": 2,
      "z": 10
    },
    {
      "color": {
        "a": 255,
        "b": 201,
        "g": 201,
        "r": 201
      },
      "x": 7,
      "y": 2,
      "z": 9
    },
    {
      "color": {
        "a": 255,
        "b": 201,
        "g": 201,
        "r": 201
      },
      "x": 6,
      "y": 2,
      "z": 10
    },
    {
      "color": {
        "a": 255,
        "b": 201,
        "g": 201,
        "r": 201
      },
      "x": 6,
      "y": 2,
      "z": 9
    },
    {
      "color": {
        "a": 255,
        "b": 201,
        "g": 201,
        "r": 201
      },
      "x": 6,
      "y": 2,
      "z": 8
    },
    {
      "color": {
        "a": 255,
        "b": 201,
        "g": 201,
        "r": 201
      },
      "x": 6,
      "y": 2,
      "z": 7
    },
    {
      "color": {
        "a": 255,
        "b": 201,
        "g": 201,
        "r": 201
      },
      "x": 5,
      "y": 2,
      "z": 10
    },
    {
      "color": {
        "a": 255,
        "b": 201,
        "g": 201,
        "r": 201
      },
      "x": 5,
      "y": 2,
      "z": 9
    },
    {
      "color": {
        "a": 255,
        "b": 201,
        "g": 201,
        "r": 201
      },
      "x": 5,
      "y": 2,
      "z": 6
    },
    {
      "color": {
        "a": 255,
        "b": 201,
        "g": 201,
        "r": 201
      },
      "x": 7,
      "y": 2,
      "z": 6
    },
    {
      "color": {
        "a": 255,
        "b": 201,
        "g": 201,
        "r": 201
      },
      "x": 6,
      "y": 2,
      "z": 6
    },
    {
      "color": {
        "a": 255,
        "b": 201,
        "g": 201,
        "r": 201
      },
      "x": 10,
      "y": 1,
      "z": 8
    },
    {
      "color": {
        "a": 255,
        "b": 201,
        "g": 201,
        "r": 201
      },
      "x": 10,
      "y": 1,
      "z": 10
    },
    {
      "color": {
        "a": 255,
        "b": 201,
        "g": 201,
        "r": 201
      },
      "x": 10,
      "y": 1,
      "z": 11
    },
    {
      "color": {
        "a": 255,
        "b": 201,
        "g": 201,
        "r": 201
      },
      "x": 5,
      "y": 1,
      "z": 10
    },
    {
      "color": {
        "a": 255,
        "b": 201,
        "g": 201,
        "r": 201
      },
      "x": 5,
      "y": 1,
      "z": 11
    },
    {
      "color": {
        "a": 255,
        "b": 201,
        "g": 201,
        "r": 201
      },
      "x": 7,
      "y": 1,
      "z": 11
    },
    {
      "color": {
        "a": 255,
        "b": 201,
        "g": 201,
        "r": 201
      },
      "x": 9,
      "y": 1,
      "z": 11
    },
    {
      "color": {
        "a": 255,
        "b": 201,
        "g": 201,
        "r": 201
      },
      "x": 9,
      "y": 1,
      "z": 10
    },
    {
      "color": {
        "a": 255,
        "b": 201,
        "g": 201,
        "r": 201
      },
      "x": 9,
      "y": 6,
      "z": 6
    },
    {
      "color": {
        "a": 255,
        "b": 201,
        "g": 201,
        "r": 201
      },
      "x": 9,
      "y": 1,
      "z": 9
    },
    {
      "color": {
        "a": 255,
        "b": 201,
        "g": 201,
        "r": 201
      },
      "x": 9,
      "y": 1,
      "z": 8
    },
    {
      "color": {
        "a": 255,
        "b": 201,
        "g": 201,
        "r": 201
      },
      "x": 9,
      "y": 1,
      "z": 7
    },
    {
      "color": {
        "a": 255,
        "b": 134,
        "g": 134,
        "r": 134
      },
      "x": 5,
      "y": 4,
      "z": 11
    },
    {
      "color": {
        "a": 255,
        "b": 134,
        "g": 134,
        "r": 134
      },
      "x": 6,
      "y": 4,
      "z": 11
    },
    {
      "color": {
        "a": 255,
        "b": 134,
        "g": 134,
        "r": 134
      },
      "x": 9,
      "y": 5,
      "z": 11
    },
    {
      "color": {
        "a": 255,
        "b": 134,
        "g": 134,
        "r": 134
      },
      "x": 9,
      "y": 4,
      "z": 11
    },
    {
      "color": {
        "a": 255,
        "b": 134,
        "g": 134,
        "r": 134
      },
      "x": 10,
      "y": 4,
      "z": 11
    },
    {
      "color": {
        "a": 255,
        "b": 65,
        "g": 65,
        "r": 65
      },
      "x": 7,
      "y": 4,
      "z": 11
    },
    {
      "color": {
        "a": 255,
        "b": 65,
        "g": 65,
        "r": 65
      },
      "x": 8,
      "y": 4,
      "z": 11
    },
    {
      "color": {
        "a": 255,
        "b": 153,
        "g": 153,
        "r": 153
      },
      "x": 5,
      "y": 3,
      "z": 11
    },
    {
      "color": {
        "a": 255,
        "b": 153,
        "g": 153,
        "r": 153
      },
      "x": 9,
      "y": 3,
      "z": 11
    },
    {
      "color": {
        "a": 255,
        "b": 153,
        "g": 153,
        "r": 153
      },
      "x": 10,
      "y": 3,
      "z": 11
    },
    {
      "color": {
        "a": 255,
        "b": 135,
        "g": 135,
        "r": 135
      },
      "x": 7,
      "y": 3,
      "z": 11
    },
    {
      "color": {
        "a": 255,
        "b": 134,
        "g": 134,
        "r": 134
      },
      "x": 10,
      "y": 5,
      "z": 11
    },
    {
      "color": {
        "a": 255,
        "b": 134,
        "g": 134,
        "r": 134
      },
      "x": 10,
      "y": 5,
      "z": 10
    },
    {
      "color": {
        "a": 255,
        "b": 134,
        "g": 134,
        "r": 134
      },
      "x": 10,
      "y": 4,
      "z": 10
    },
    {
      "color": {
        "a": 255,
        "b": 134,
        "g": 134,
        "r": 134
      },
      "x": 10,
      "y": 4,
      "z": 9
    },
    {
      "color": {
        "a": 255,
        "b": 134,
        "g": 134,
        "r": 134
      },
      "x": 10,
      "y": 5,
      "z": 9
    },
    {
      "color": {
        "a": 255,
        "b": 134,
        "g": 134,
        "r": 134
      },
      "x": 10,
      "y": 5,
      "z": 8
    },
    {
      "color": {
        "a": 255,
        "b": 134,
        "g": 134,
        "r": 134
      },
      "x": 10,
      "y": 4,
      "z": 8
    },
    {
      "color": {
        "a": 255,
        "b": 134,
        "g": 134,
        "r": 134
      },
      "x": 10,
      "y": 5,
      "z": 7
    },
    {
      "color": {
        "a": 255,
        "b": 134,
        "g": 134,
        "r": 134
      },
      "x": 10,
      "y": 4,
      "z": 7
    },
    {
      "color": {
        "a": 255,
        "b": 134,
        "g": 134,
        "r": 134
      },
      "x": 10,
      "y": 5,
      "z": 6
    },
    {
      "color": {
        "a": 255,
        "b": 134,
        "g": 134,
        "r": 134
      },
      "x": 10,
      "y": 4,
      "z": 6
    },
    {
      "color": {
        "a": 255,
        "b": 134,
        "g": 134,
        "r": 134
      },
      "x": 9,
      "y": 5,
      "z": 6
    },
    {
      "color": {
        "a": 255,
        "b": 134,
        "g": 134,
        "r": 134
      },
      "x": 9,
      "y": 4,
      "z": 6
    },
    {
      "color": {
        "a": 255,
        "b": 134,
        "g": 134,
        "r": 134
      },
      "x": 8,
      "y": 4,
      "z": 6
    },
    {
      "color": {
        "a": 255,
        "b": 134,
        "g": 134,
        "r": 134
      },
      "x": 7,
      "y": 5,
      "z": 6
    },
    {
      "color": {
        "a": 255,
        "b": 134,
        "g": 134,
        "r": 134
      },
      "x": 7,
      "y": 4,
      "z": 6
    },
    {
      "color": {
        "a": 255,
        "b": 134,
        "g": 134,
        "r": 134
      },
      "x": 6,
      "y": 4,
      "z": 6
    },
    {
      "color": {
        "a": 255,
        "b": 134,
        "g": 134,
        "r": 134
      },
      "x": 5,
      "y": 4,
      "z": 6
    },
    {
      "color": {
        "a": 255,
        "b": 134,
        "g": 134,
        "r": 134
      },
      "x": 5,
      "y": 5,
      "z": 6
    },
    {
      "color": {
        "a": 255,
        "b": 134,
        "g": 134,
        "r": 134
      },
      "x": 5,
      "y": 5,
      "z": 7
    },
    {
      "color": {
        "a": 255,
        "b": 134,
        "g": 134,
        "r": 134
      },
      "x": 5,
      "y": 5,
      "z": 8
    },
    {
      "color": {
        "a": 255,
        "b": 134,
        "g": 134,
        "r": 134
      },
      "x": 5,
      "y": 5,
      "z": 9
    },
    {
      "color": {
        "a": 255,
        "b": 134,
        "g": 134,
        "r": 134
      },
      "x": 5,
      "y": 4,
      "z": 9
    },
    {
      "color": {
        "a": 255,
        "b": 134,
        "g": 134,
        "r": 134
      },
      "x": 6,
      "y": 4,
      "z": 10
    },
    {
      "color": {
        "a": 255,
        "b": 134,
        "g": 134,
        "r": 134
      },
      "x": 5,
      "y": 4,
      "z": 10
    },
    {
      "color": {
        "a": 255,
        "b": 83,
        "g": 83,
        "r": 83
      },
      "x": 10,
      "y": 8,
      "z": 11
    },
    {
      "color": {
        "a": 255,
        "b": 83,
        "g": 83,
        "r": 83
      },
      "x": 9,
      "y": 7,
      "z": 11
    },
    {
      "color": {
        "a": 255,
        "b": 201,
        "g": 201,
        "r": 201
      },
      "x": 9,
      "y": 8,
      "z": 11
    },
    {
      "color": {
        "a": 255,
        "b": 201,
        "g": 201,
        "r": 201
      },
      "x": 10,
      "y": 7,
      "z": 11
    },
    {
      "color": {
        "a": 255,
        "b": 83,
        "g": 83,
        "r": 83
      },
      "x": 7,
      "y": 6,
      "z": 11
    },
    {
      "color": {
        "a": 255,
        "b": 83,
        "g": 83,
        "r": 83
      },
      "x": 8,
      "y": 6,
      "z": 11
    },
    {
      "color": {
        "a": 255,
        "b": 201,
        "g": 201,
        "r": 201
      },
      "x": 9,
      "y": 6,
      "z": 11
    },
    {
      "color": {
        "a": 255,
        "b": 201,
        "g": 201,
        "r": 201
      },
      "x": 10,
      "y": 1,
      "z": 7
    },
    {
      "color": {
        "a": 255,
        "b": 201,
        "g": 201,
        "r": 201
      },
      "x": 6,
      "y": 2,
      "z": 11
    }
  ]
}
